Workbook

Sheet Pilot站点
A1: Node_New | B1: Tech | E1: Antenna | G1: MIMO | R1: Power | X1: Power Margin
B2: Pre | C2: Post | D2: Change | E2: Pre | F2: Post | G2: Pre | M2: Post | R2: Pre | U2: Post | X2: Low Band | AB2: High Band
G3: 700 | H3: 1900 | K3: 2600 | M3: 700 | O3: 1900 | P3: 2600 | R3: 700 | S3: 1900 | T3: 2600 | U3: 700 | V3: 1900 | W3: 2600
G4: 2T2R | H4: 1T2R | I4: 2T2R | J4: 4T4R | K4: 2T2R | L4: 4T4R | M4: 2T2R | N4: 4T4R | O4: 4T4R | P4: 2T2R | Q4: 4T4R | X4: S1 | Y4: S2 | Z4: S3 | AA4: S4 | AB4: S1 | AC4: S2 | AD4: S3 | AE4: S4
A5: BATNO | B5: B5/B7/N78 | C5: B5/B7/N78 64T64R | D5: L2L | E5: ATR4518R13 | F5: ATR4518R13 | K5: 3 | Q5: 3 | T5: 120 | W5: 240 | X5: 80 | Y5: 80 | Z5: 80 | AB5: 120 | AC5: 120 | AD5: 120 | AE5: -
A6: BATUC | B6: B5/B7 | C6: B5/B7 | D6: L2L | E6: ATR4518R13 | F6: ATR4518R13 | L6: 2 | Q6: 2 | T6: 320 | W6: 320 | X6: 80 | Y6: 80 | AB6: 100 | AC6: 100 | AD6: 0 | AE6: -
A7: BATUF | B7: B28/B5/B2/B7 | C7: B28/B5/B2/B7/N78 32T32R | D7: OVERLAY N78 | E7: ODI2-065R16MJJ02-GQ V2 | F7: ODI2-065R16MJJ02-GQ V2 | G7: 3 | J7: 3 | L7: 3 | N7: 3 | O7: 3 | Q7: 3 | R7: 60 | S7: 240 | T7: 240 | U7: 120 | V7: 240 | W7: 240 | X7: 50 | Y7: 50 | Z7: 50 | AB7: 100 | AC7: 100 | AD7: 100 | AE7: -
A8: CFUCE | B8: B28/B5/B2/B7 | C8: B28/B5/B2/B7 | D8: L2L | E8: 2G4WD-21A | F8: 2G4WD-21A | G8: 3 | J8: 3 | L8: 3 | N8: 3 | O8: 3 | Q8: 3 | R8: 60 | S8: 240 | T8: 240 | U8: 120 | V8: 240 | W8: 240 | X8: 70 | Y8: 70 | Z8: 70 | AB8: 100 | AC8: 100 | AD8: 100 | AE8: -
A9: CLIPA | B9: B28/B5/B2/B7/N78 | C9: B28/B5/B2/B7/N78 64T64R | D9: L2L | E9: ASI4517R3v06+ODP-065R17BV | F9: ASI4517R3v06+ODP-065R17BV | G9: 3 | I9: 3 | L9: 3 | N9: 3 | O9: 3 | Q9: 3 | R9: 60 | S9: 120 | T9: 320 | U9: 120 | V9: 240 | W9: 320 | X9: 50 | Y9: 50 | Z9: 50 | AA9: 80 | AB9: 100 | AC9: 100 | AD9: 80 | AE9: -
A10: COHUE | B10: B28/B5/B2/B7/N78 | C10: B28/B5/B2/B7/N78 64T64R | D10: L2L | E10: 2G4WD-21A | F10: 2G4WD-21A | G10: 3 | J10: 3 | L10: 2 | N10: 3 | O10: 3 | Q10: 2 | R10: 120 | S10: 240 | T10: 320 | U10: 240 | V10: 240 | W10: 320 | X10: 60 | Y10: 60 | Z10: 60 | AB10: 80 | AC10: 80 | AD10: 120 | AE10: -
A11: COINP | B11: B5/B7/N78 | C11: B5/B7/N78 64T64R | D11: L2L | E11: ASI4518R64v06 | F11: ASI4518R64v06 | L11: 3 | Q11: 3 | T11: 480 | W11: 480 | X11: 80 | Y11: 80 | Z11: 80 | AB11: 100 | AC11: 100 | AD11: 100 | AE11: -
A12: CPQG1 | B12: B5/B7/N78 | C12: B5/B7/N78 64T64R | D12: L2L | E12: APXV86-906513L+W2X-6516DS-VTM | F12: APXV86-906513L+W2X-6516DS-VTM | K12: 3 | P12: 3 | T12: 240 | W12: 240 | X12: 80 | Y12: 100 | Z12: 100 | AB12: 100 | AC12: 100 | AD12: 100 | AE12: -
A13: CTREN | B13: B28/N78 | C13: B28/B5/N78 64T64R | D13: OVERLAY B5 | E13: ATR4518R13 | F13: ATR4518R13 | G13: 3 | M13: 3 | R13: 120 | U13: 120 | X13: 80 | Y13: 80 | Z13: 80 | AB13: - | AC13: - | AD13: - | AE13: -
A14: DHLMF | B14: B28/B5/B2/B7/N78 | C14: B28/B5/B2/B7/N78 64T64R | D14: L2L | E14: 2G4WD-21A | F14: 2G4WD-21A | G14: 3 | J14: 3 | L14: 3 | N14: 3 | O14: 3 | Q14: 3 | R14: 120 | S14: 240 | T14: 480 | U14: 240 | V14: 240 | W14: 480 | X14: 60 | Y14: 60 | Z14: 60 | AB14: 80 | AC14: 80 | AD14: 80 | AE14: -
A15: DHUEF | B15: B28/B5/B2/B7/N78 | C15: B28/B5/B2/B7/N78 64T64R | D15: L2L | E15: ASI4517R3v06 | F15: ASI4517R3v06 | G15: 3 | I15: 3 | L15: 3 | N15: 3 | O15: 3 | Q15: 3 | R15: 120 | S15: 240 | T15: 480 | U15: 240 | V15: 480 | W15: 480 | X15: 60 | Y15: 60 | Z15: 60 | AB15: 60 | AC15: 60 | AD15: 60 | AE15: -
A16: JBALI | B16: B28/B5/B2/B7 | C16: B28/B5/B2/B7 | D16: L2L | E16: 2G4WD-21A | F16: 2G4WD-21A | G16: 3 | J16: 3 | L16: 3 | N16: 3 | O16: 3 | Q16: 3 | R16: 60 | S16: 240 | T16: 480 | U16: 120 | V16: 240 | W16: 480 | X16: 70 | Y16: 70 | Z16: 70 | AB16: 80 | AC16: 80 | AD16: 80 | AE16: -
A17: LAMP2 | B17: B28/B5/B2/B7 | C17: B28/B5/B2/B7/N78 32T32R | D17: OVERLAY N78 | E17: FASC_087623A | F17: New Antennna | G17: 3 | J17: 3 | K17: 3 | N17: 3 | O17: 3 | Q17: 3 | R17: 60 | S17: 240 | T17: 240 | U17: 120 | V17: 240 | W17: 480 | X17: 70 | Y17: 70 | Z17: 70 | AB17: 80 | AC17: 80 | AD17: 80 | AE17: -
A18: LARAL | B18: B28/B5/B2/B7 | C18: B28/B5/B2/B7 | D18: L2L | E18: 2G4WD-21A | F18: 2G4WD-21A | G18: 3 | J18: 3 | L18: 4 | N18: 3 | O18: 3 | Q18: 4 | R18: 60 | S18: 240 | T18: 640 | U18: 120 | V18: 240 | W18: 640 | X18: 70 | Y18: 70 | Z18: 70 | AB18: 80 | AC18: 80 | AD18: 80 | AE18: 100
A19: LARIB | B19: B28/B5/B2/B7 | C19: B28/B5/B2/B7/N78 32T32R | D19: OVERLAY N78 | E19: ODI-065R16MM18JJJ-GQ | F19: ODI-065R16MM18JJJ-GQ | G19: 3 | J19: 3 | K19: 3 | N19: 3 | O19: 3 | Q19: 3 | R19: 60 | S19: 320 | T19: 240 | U19: 120 | V19: 320 | W19: 480 | X19: 70 | Y19: 70 | Z19: 70 | AB19: 60 | AC19: 80 | AD19: 80 | AE19: -
A20: LMPF2 | B20: B28/B5/B2/B7 | C20: B28/B5/B2/B7/N78 32T32R | D20: OVERLAY N78 | E20: ASI4517R3v06 | F20: ASI4517R3v06 | G20: 3 | J20: 3 | L20: 3 | N20: 3 | O20: 3 | Q20: 3 | R20: 60 | S20: 240 | T20: 480 | U20: 120 | V20: 240 | W20: 480 | X20: 50 | Y20: 50 | Z20: 50 | AB20: 80 | AC20: 80 | AD20: 80 | AE20: -
A21: LOMIA | B21: B28/B5/B2/B7/N78 | C21: B28/B5/B2/B7/N78 64T64R | D21: L2L | E21: ASI4517R3v06 | F21: ASI4517R3v06 | G21: 3 | J21: 3 | L21: 3 | N21: 3 | O21: 3 | Q21: 3 | R21: 120 | S21: 240 | T21: 480 | U21: 240 | V21: 240 | W21: 480 | X21: 60 | Y21: 60 | Z21: 60 | AB21: 80 | AC21: 80 | AD21: 80 | AE21: -
A22: OLIBA | B22: B28/B5 | C22: B28/B5 | D22: L2L | E22: 2G4WD-21A | F22: 2G4WD-21A | G22: 2 | N22: 2 | R22: 80 | U22: 160 | X22: 60 | Y22: 60 | AB22: - | AC22: - | AD22: - | AE22: -
A23: RIFLO | B23: B5/B7/N78 | C23: B5/B7/N78 64T64R | D23: L2L | E23: ASI4518R64v06 | F23: ASI4518R64v06 | L23: 3 | Q23: 3 | T23: 480 | W23: 480 | X23: 80 | Y23: 80 | Z23: 80 | AB23: 100 | AC23: 100 | AD23: 100 | AE23: -
A24: VNCRZ | B24: B28/B5/B2/B7/N78 | C24: B28/B5/B2/B7/N78 64T64R | D24: L2L | E24: 80010991 | F24: 80010991 | G24: 3 | H24: 3 | L24: 3 | N24: 3 | O24: 3 | Q24: 3 | R24: 120 | S24: 120 | T24: 480 | U24: 240 | V24: 480 | W24: 480 | X24: 60 | Y24: 60 | Z24: 60 | AB24: 60 | AC24: 60 | AD24: 60 | AE24: -
E35: Band | F35: 现网站点 | G35: 现网4T4R数量 | H35: 现网4T4R占比 | I35: 替换后站点 | J35: 替换后4T4R数量 | K35: 替换后4T4R占比
E36: 700M | F36: 383 | G36: 0 | H36: 0 | I36: 398 | J36: 271 | K36: 0.68
E37: 1900M | F37: 288 | G37: 194 | H37: 0.67 | I37: 313 | J37: 308 | K37: 0.98
E38: 2600M | F38: 641 | G38: 180 | H38: 0.28 | I38: 651 | J38: 524 | K38: 0.8

Sheet Verson Update
A1: Verson | B1: Update | C1: Update Date
A2: V1.1.1 | B2: Pilot planning（9） | C2: 46184
A3: V1.1.2 | B3: 高优先级站点（46） | C3: 46187

Sheet RF Parameter
A1: Site Name | B1: NE Name | C1: Existing vendor | D1: Comment | E1: Split | F1: Site latitude | G1: Site longitude | H1: Cell Name_Existing | I1: Cell Name_New | K1: Sector | L1: Tech | M1: Band | N1: Antenna_Mbitel | O1: Antenna height_Mbitel | P1: Antenna azimuth_Mbitel | Q1: E_Tilt_Mobitel | R1: M_Tilt_Mobitel | S1: Antenna_TSSR | T1: Antenna height_TSSR | U1: Antenna azimuth_TSSR | V1: Mechanical tilt_TSSR | W1: Electrical tilt_TSSR | X1: TSSR Status | Y1: MIMO_Existing | Z1: 天线最大端口数 | AA1: MIMO_New | AB1: RRU Type | AC1: RRU Type_2 | AD1: Antenna_Plan | AE1: Antenna height_Plan | AF1: Antenna azimuth_Plan | AG1: Mechanical tilt_Plan | AH1: Electrical tilt_Plan | AI1: FDD\TDD | AL1: comment
A2: GMDAD1 | B2: GMDAD1_G_Dadagamuwa_8_Gm | C2: Huawei | F2: 7.13907 | G2: 80.0639 | H2: GMDAD1P | K2: S1 | L2: 2G | M2: 1800 | N2: AQU4518R9v06 | O2: 0 | P2: 90 | R2: 2 | AA2: 1T1R | AB2: R9264 M1821N | AC2: R9254E S8500*2+R9264 M1821N*3 | AD2: AQU4518R9v06 | AE2: 0 | AF2: 90 | AH2: 2 | AL2: pilot'
A3: GMDAD1 | B3: GMDAD1_G_Dadagamuwa_8_Gm | C3: Huawei | F3: 7.13907 | G3: 80.0639 | H3: GMDAD1Q | K3: S2 | L3: 2G | M3: 1800 | N3: AQU4518R9v06 | O3: 0 | P3: 210 | R3: 2 | AA3: 1T1R | AB3: R9264 M1821N | AC3: R9254E S8500*2+R9264 M1821N*3 | AD3: AQU4518R9v06 | AE3: 0 | AF3: 210 | AH3: 2 | AL3: pilot'
A4: GMDAD1 | B4: GMDAD1_G_Dadagamuwa_8_Gm | C4: Huawei | F4: 7.13907 | G4: 80.0639 | H4: GMDAD1R | K4: S3 | L4: 2G | M4: 1800 | N4: AQU4518R9v06 | O4: 0 | P4: 330 | R4: 2 | AA4: 1T1R | AB4: R9264 M1821N | AC4: R9254E S8500*2+R9264 M1821N*3 | AD4: AQU4518R9v06 | AE4: 0 | AF4: 330 | AH4: 2 | AL4: pilot'
A5: GMDAD1 | B5: GMDAD1_G0L00_Dadagamuwa_IP_Gm | C5: Huawei | F5: 7.13907 | G5: 80.0639 | H5: GMDAD1-M-L21-A2 | K5: S1 | L5: 4G | M5: 2100 | N5: AQU4518R9v06 | O5: 50 | P5: 90 | R5: 0 | Y5: 2T2R | Z5: 6T6R | AA5: 4T4R | AB5: R9264 M1821N | AC5: R9254E S8500*2+R9264 M1821N*3 | AD5: AQU4518R9v06 | AE5: 50 | AF5: 90 | AH5: 0 | AI5: =_xlfn.XLOOKUP(A5,'[2]177+10+50 Sites (detail)'!$B:$B,'[2]177+10+50 Sites (detail)'!$I:$I) | AJ5: =_xlfn.XLOOKUP(A5,[3]最小距离站点!$A:$A,[3]最小距离站点!$B:$B) | AK5: =_xlfn.XLOOKUP(A5,[3]最小距离站点!$A:$A,[3]最小距离站点!$C:$C) | AL5: pilot'
A6: GMDAD1 | B6: GMDAD1_G0L00_Dadagamuwa_IP_Gm | C6: Huawei | F6: 7.13907 | G6: 80.0639 | H6: GMDAD1G | K6: S1 | L6: 4G | M6: 1800 | N6: AQU4518R9v06 | O6: 50 | P6: 90 | R6: 0 | Y6: 2T2R | Z6: 6T6R | AA6: 4T4R | AB6: R9264 M1821N | AC6: R9254E S8500*2+R9264 M1821N*3 | AD6: AQU4518R9v06 | AE6: 50 | AF6: 90 | AH6: 0 | AI6: =_xlfn.XLOOKUP(A6,'[2]177+10+50 Sites (detail)'!$B:$B,'[2]177+10+50 Sites (detail)'!$I:$I) | AJ6: =_xlfn.XLOOKUP(A6,[3]最小距离站点!$A:$A,[3]最小距离站点!$B:$B) | AK6: =_xlfn.XLOOKUP(A6,[3]最小距离站点!$A:$A,[3]最小距离站点!$C:$C) | AL6: pilot'
A7: GMDAD1 | B7: GMDAD1_G0L00_Dadagamuwa_IP_Gm | C7: Huawei | F7: 7.13907 | G7: 80.0639 | H7: GMDAD1-M-L85-A1 | K7: S1 | L7: 4G | M7: 850 | N7: AQU4518R9v06 | O7: 50 | P7: 90 | R7: 0 | Y7: 2T2R | Z7: 2T2R | AA7: 2T2R | AB7: R9254E S8500 | AC7: R9254E S8500*2+R9264 M1821N*3 | AD7: AQU4518R9v06 | AE7: 50 | AF7: 90 | AH7: 0 | AI7: =_xlfn.XLOOKUP(A7,'[2]177+10+50 Sites (detail)'!$B:$B,'[2]177+10+50 Sites (detail)'!$I:$I) | AJ7: =_xlfn.XLOOKUP(A7,[3]最小距离站点!$A:$A,[3]最小距离站点!$B:$B) | AK7: =_xlfn.XLOOKUP(A7,[3]最小距离站点!$A:$A,[3]最小距离站点!$C:$C) | AL7: pilot'
A8: GMDAD1 | B8: GMDAD1_G0L00_Dadagamuwa_IP_Gm | C8: Huawei | F8: 7.13907 | G8: 80.0639 | H8: GMDAD1-M-L21-B2 | K8: S2 | L8: 4G | M8: 2100 | N8: AQU4518R9v06 | O8: 50 | P8: 210 | R8: 0 | Y8: 2T2R | Z8: 6T6R | AA8: 4T4R | AB8: R9264 M1821N | AC8: R9254E S8500*2+R9264 M1821N*3 | AD8: AQU4518R9v06 | AE8: 50 | AF8: 210 | AH8: 0 | AI8: =_xlfn.XLOOKUP(A8,'[2]177+10+50 Sites (detail)'!$B:$B,'[2]177+10+50 Sites (detail)'!$I:$I) | AJ8: =_xlfn.XLOOKUP(A8,[3]最小距离站点!$A:$A,[3]最小距离站点!$B:$B) | AK8: =_xlfn.XLOOKUP(A8,[3]最小距离站点!$A:$A,[3]最小距离站点!$C:$C) | AL8: pilot'
A9: GMDAD1 | B9: GMDAD1_G0L00_Dadagamuwa_IP_Gm | C9: Huawei | F9: 7.13907 | G9: 80.0639 | H9: GMDAD1H | K9: S2 | L9: 4G | M9: 1800 | N9: AQU4518R9v06 | O9: 50 | P9: 210 | R9: 0 | Y9: 2T2R | Z9: 6T6R | AA9: 4T4R | AB9: R9264 M1821N | AC9: R9254E S8500*2+R9264 M1821N*3 | AD9: AQU4518R9v06 | AE9: 50 | AF9: 210 | AH9: 0 | AI9: =_xlfn.XLOOKUP(A9,'[2]177+10+50 Sites (detail)'!$B:$B,'[2]177+10+50 Sites (detail)'!$I:$I) | AJ9: =_xlfn.XLOOKUP(A9,[3]最小距离站点!$A:$A,[3]最小距离站点!$B:$B) | AK9: =_xlfn.XLOOKUP(A9,[3]最小距离站点!$A:$A,[3]最小距离站点!$C:$C) | AL9: pilot'
A10: GMDAD1 | B10: GMDAD1_G0L00_Dadagamuwa_IP_Gm | C10: Huawei | F10: 7.13907 | G10: 80.0639 | H10: GMDAD1-M-L85-B1 | K10: S2 | L10: 4G | M10: 850 | N10: AQU4518R9v06 | O10: 50 | P10: 210 | R10: 0 | Y10: 2T2R | Z10: 2T2R | AA10: 2T2R | AB10: R9254E S8500 | AC10: R9254E S8500*2+R9264 M1821N*3 | AD10: AQU4518R9v06 | AE10: 50 | AF10: 210 | AH10: 0 | AI10: =_xlfn.XLOOKUP(A10,'[2]177+10+50 Sites (detail)'!$B:$B,'[2]177+10+50 Sites (detail)'!$I:$I) | AJ10: =_xlfn.XLOOKUP(A10,[3]最小距离站点!$A:$A,[3]最小距离站点!$B:$B) | AK10: =_xlfn.XLOOKUP(A10,[3]最小距离站点!$A:$A,[3]最小距离站点!$C:$C) | AL10: pilot'
A11: GMDAD1 | B11: GMDAD1_G0L00_Dadagamuwa_IP_Gm | C11: Huawei | F11: 7.13907 | G11: 80.0639 | H11: GMDAD1-M-L21-C2 | K11: S3 | L11: 4G | M11: 2100 | N11: AQU4518R9v06 | O11: 50 | P11: 330 | R11: 0 | Y11: 2T2R | Z11: 6T6R | AA11: 4T4R | AB11: R9264 M1821N | AC11: R9254E S8500*2+R9264 M1821N*3 | AD11: AQU4518R9v06 | AE11: 50 | AF11: 330 | AH11: 0 | AI11: =_xlfn.XLOOKUP(A11,'[2]177+10+50 Sites (detail)'!$B:$B,'[2]177+10+50 Sites (detail)'!$I:$I) | AJ11: =_xlfn.XLOOKUP(A11,[3]最小距离站点!$A:$A,[3]最小距离站点!$B:$B) | AK11: =_xlfn.XLOOKUP(A11,[3]最小距离站点!$A:$A,[3]最小距离站点!$C:$C) | AL11: pilot'
A12: GMDAD1 | B12: GMDAD1_G0L00_Dadagamuwa_IP_Gm | C12: Huawei | F12: 7.13907 | G12: 80.0639 | H12: GMDAD1I | K12: S3 | L12: 4G | M12: 1800 | N12: AQU4518R9v06 | O12: 50 | P12: 330 | R12: 0 | Y12: 2T2R | Z12: 6T6R | AA12: 4T4R | AB12: R9264 M1821N | AC12: R9254E S8500*2+R9264 M1821N*3 | AD12: AQU4518R9v06 | AE12: 50 | AF12: 330 | AH12: 0 | AI12: =_xlfn.XLOOKUP(A12,'[2]177+10+50 Sites (detail)'!$B:$B,'[2]177+10+50 Sites (detail)'!$I:$I) | AJ12: =_xlfn.XLOOKUP(A12,[3]最小距离站点!$A:$A,[3]最小距离站点!$B:$B) | AK12: =_xlfn.XLOOKUP(A12,[3]最小距离站点!$A:$A,[3]最小距离站点!$C:$C) | AL12: pilot'
A13: GMDAD1 | B13: GMDAD1_G0L00_Dadagamuwa_IP_Gm | C13: Huawei | F13: 7.13907 | G13: 80.0639 | H13: GMDAD1-M-L85-C1 | K13: S3 | L13: 4G | M13: 850 | N13: AQU4518R9v06 | O13: 50 | P13: 330 | R13: 0 | Y13: 2T2R | Z13: 2T2R | AA13: 2T2R | AB13: R9254E S8500 | AC13: R9254E S8500*2+R9264 M1821N*3 | AD13: AQU4518R9v06 | AE13: 50 | AF13: 330 | AH13: 0 | AI13: =_xlfn.XLOOKUP(A13,'[2]177+10+50 Sites (detail)'!$B:$B,'[2]177+10+50 Sites (detail)'!$I:$I) | AJ13: =_xlfn.XLOOKUP(A13,[3]最小距离站点!$A:$A,[3]最小距离站点!$B:$B) | AK13: =_xlfn.XLOOKUP(A13,[3]最小距离站点!$A:$A,[3]最小距离站点!$C:$C) | AL13: pilot'
A14: GMKAL2 | B14: GMKAL2_G_Kalagedihena__89__Gm | C14: Huawei | F14: 7.117603 | G14: 80.06068 | H14: GMKAL2P | K14: S1 | L14: 2G | M14: 1800 | N14: AQU4518R9v06 | O14: 0 | P14: 40 | R14: 2 | Y14: 1T1R | AA14: 1T1R | AB14: R9264H M901821 | AC14: A9652 S35*3+R9264H M901821*4+R9254E S8500*2+FL8590A*4 | AD14: AQU4518R9v06 | AE14: 0 | AF14: 40 | AH14: 2 | AL14: pilot'
A15: GMKAL2 | B15: GMKAL2_G_Kalagedihena__89__Gm | C15: Huawei | F15: 7.117603 | G15: 80.06068 | H15: GMKAL2A | K15: S1 | L15: 2G | M15: 900 | N15: AQU4518R9v06 | O15: 0 | P15: 40 | R15: 2 | AA15: 1T1R | AB15: R9264H M901821 | AC15: A9652 S35*3+R9264H M901821*4+R9254E S8500*2+FL8590A*4 | AD15: AQU4518R9v06 | AE15: 0 | AF15: 40 | AH15: 2 | AL15: pilot'
A16: GMKAL2 | B16: GMKAL2_G_Kalagedihena__89__Gm | C16: Huawei | F16: 7.117603 | G16: 80.06068 | H16: GMKAL2Q | K16: S2 | L16: 2G | M16: 1800 | N16: AQU4518R9v06 | O16: 0 | P16: 165 | R16: 2 | Y16: 1T1R | AA16: 1T1R | AB16: R9264H M901821 | AC16: A9652 S35*3+R9264H M901821*4+R9254E S8500*2+FL8590A*4 | AD16: AQU4518R9v06 | AE16: 0 | AF16: 165 | AH16: 2 | AL16: pilot'
A17: GMKAL2 | B17: GMKAL2_G_Kalagedihena__89__Gm | C17: Huawei | F17: 7.117603 | G17: 80.06068 | H17: GMKAL2B | K17: S2 | L17: 2G | M17: 900 | N17: AQU4518R9v06 | O17: 0 | P17: 165 | R17: 2 | AA17: 1T1R | AB17: R9264H M901821 | AC17: A9652 S35*3+R9264H M901821*4+R9254E S8500*2+FL8590A*4 | AD17: AQU4518R9v06 | AE17: 0 | AF17: 165 | AH17: 2 | AL17: pilot'
A18: GMKAL2 | B18: GMKAL2_G_Kalagedihena__89__Gm | C18: Huawei | F18: 7.118 | G18: 80.0572 | H18: GMKAL2R | K18: S3 | L18: 2G | M18: 1800 | N18: AQU4518R9v06 | O18: 0 | P18: 220 | R18: 2 | Y18: 1T1R | AA18: 1T1R | AB18: R9264H M901821 | AC18: A9652 S35*3+R9264H M901821*4+R9254E S8500*2+FL8590A*4 | AD18: AQU4518R9v06 | AE18: 0 | AF18: 220 | AH18: 2 | AL18: pilot'
A19: GMKAL2 | B19: GMKAL2_G_Kalagedihena__89__Gm | C19: Huawei | F19: 7.117603 | G19: 80.06068 | H19: GMKAL2C | K19: S3 | L19: 2G | M19: 900 | N19: AQU4518R9v06 | O19: 0 | P19: 240 | R19: 2 | AA19: 1T1R | AB19: R9264H M901821 | AC19: A9652 S35*3+R9264H M901821*4+R9254E S8500*2+FL8590A*4 | AD19: AQU4518R9v06 | AE19: 0 | AF19: 240 | AH19: 2 | AL19: pilot'
A20: GMKAL2 | B20: GMKAL2_G_Kalagedihena__89__Gm | C20: Huawei | F20: 7.11759 | G20: 80.0607 | H20: GMKAL2S | K20: S4 | L20: 2G | M20: 1800 | N20: AQU4518R9v06 | O20: 0 | P20: 285 | R20: 2 | Y20: 1T1R | AA20: 1T1R | AB20: R9264H M901821 | AC20: A9652 S35*3+R9264H M901821*4+R9254E S8500*2+FL8590A*4 | AD20: AQU4518R9v06 | AE20: 0 | AF20: 285 | AH20: 2 | AL20: pilot'
A21: GMKAL2 | B21: GMKAL2_G_Kalagedihena__89__Gm | C21: Huawei | F21: 7.117603 | G21: 80.06068 | H21: GMKAL2D | K21: S4 | L21: 2G | M21: 900 | N21: AQU4518R9v06 | O21: 0 | P21: 285 | R21: 2 | AA21: 1T1R | AB21: R9264H M901821 | AC21: A9652 S35*3+R9264H M901821*4+R9254E S8500*2+FL8590A*4 | AD21: AQU4518R9v06 | AE21: 0 | AF21: 285 | AH21: 2 | AL21: pilot'
A22: GMKAL2 | B22: GMKAL2_GUL00_Kalagedihena_Gm | C22: Huawei | F22: 7.117603 | G22: 80.06068 | H22: GMKAL2-M-L21-A2 | K22: S1 | L22: 4G | M22: 2100 | N22: AQU4518R9v06 | O22: 70 | P22: 40 | R22: 0 | Y22: =_xlfn.XLOOKUP(H22,'[1]4G Parameters'!$G:$G,'[1]4G Parameters'!$AA:$AA) | Z22: 6T6R | AA22: 4TR | AB22: R9264H M901821 | AC22: A9652 S35*3+R9264H M901821*4+R9254E S8500*2+FL8590A*4 | AD22: AQU4518R9v06 | AE22: 70 | AF22: 40 | AH22: 0 | AI22: =_xlfn.XLOOKUP(A22,'[2]177+10+50 Sites (detail)'!$B:$B,'[2]177+10+50 Sites (detail)'!$I:$I) | AJ22: =_xlfn.XLOOKUP(A22,[3]最小距离站点!$A:$A,[3]最小距离站点!$B:$B) | AK22: =_xlfn.XLOOKUP(A22,[3]最小距离站点!$A:$A,[3]最小距离站点!$C:$C) | AL22: pilot'
A23: GMKAL2 | B23: GMKAL2_GUL00_Kalagedihena_Gm | C23: Huawei | F23: 7.117603 | G23: 80.06068 | H23: GMKAL2G | K23: S1 | L23: 4G | M23: 1800 | N23: AQU4518R9v06 | O23: 70 | P23: 40 | R23: 0 | Y23: =_xlfn.XLOOKUP(H23,'[1]4G Parameters'!$G:$G,'[1]4G Parameters'!$AA:$AA) | Z23: 6T6R | AA23: 4TR | AB23: R9264H M901821 | AC23: A9652 S35*3+R9264H M901821*4+R9254E S8500*2+FL8590A*4 | AD23: AQU4518R9v06 | AE23: 70 | AF23: 40 | AH23: 0 | AI23: =_xlfn.XLOOKUP(A23,'[2]177+10+50 Sites (detail)'!$B:$B,'[2]177+10+50 Sites (detail)'!$I:$I) | AJ23: =_xlfn.XLOOKUP(A23,[3]最小距离站点!$A:$A,[3]最小距离站点!$B:$B) | AK23: =_xlfn.XLOOKUP(A23,[3]最小距离站点!$A:$A,[3]最小距离站点!$C:$C) | AL23: pilot'
A24: GMKAL2 | B24: GMKAL2_GUL00_Kalagedihena_Gm | C24: Huawei | F24: 7.117603 | G24: 80.06068 | H24: GMKAL2-M-L85-A1 | K24: S1 | L24: 4G | M24: 850 | N24: AQU4518R9v06 | O24: 70 | P24: 40 | R24: 0 | Y24: =_xlfn.XLOOKUP(H24,'[1]4G Parameters'!$G:$G,'[1]4G Parameters'!$AA:$AA) | Z24: 2T2R | AA24: 2T2R | AB24: R9254E S8500 | AC24: A9652 S35*3+R9264H M901821*4+R9254E S8500*2+FL8590A*4 | AD24: AQU4518R9v06 | AE24: 70 | AF24: 40 | AH24: 0 | AI24: =_xlfn.XLOOKUP(A24,'[2]177+10+50 Sites (detail)'!$B:$B,'[2]177+10+50 Sites (detail)'!$I:$I) | AJ24: =_xlfn.XLOOKUP(A24,[3]最小距离站点!$A:$A,[3]最小距离站点!$B:$B) | AK24: =_xlfn.XLOOKUP(A24,[3]最小距离站点!$A:$A,[3]最小距离站点!$C:$C) | AL24: pilot'
A25: GMKAL2 | B25: GMKAL2_GUL00_Kalagedihena_Gm | C25: Huawei | F25: 7.117603 | G25: 80.06068 | H25: GMKAL2-M-L21-B2 | K25: S2 | L25: 4G | M25: 2100 | N25: AQU4518R9v06 | O25: 70 | P25: 165 | R25: 0 | Y25: =_xlfn.XLOOKUP(H25,'[1]4G Parameters'!$G:$G,'[1]4G Parameters'!$AA:$AA) | Z25: 6T6R | AA25: 4TR | AB25: R9264H M901821 | AC25: A9652 S35*3+R9264H M901821*4+R9254E S8500*2+FL8590A*4 | AD25: AQU4518R9v06 | AE25: 70 | AF25: 165 | AH25: 0 | AI25: =_xlfn.XLOOKUP(A25,'[2]177+10+50 Sites (detail)'!$B:$B,'[2]177+10+50 Sites (detail)'!$I:$I) | AJ25: =_xlfn.XLOOKUP(A25,[3]最小距离站点!$A:$A,[3]最小距离站点!$B:$B) | AK25: =_xlfn.XLOOKUP(A25,[3]最小距离站点!$A:$A,[3]最小距离站点!$C:$C) | AL25: pilot'
A26: GMKAL2 | B26: GMKAL2_GUL00_Kalagedihena_Gm | C26: Huawei | F26: 7.117603 | G26: 80.06068 | H26: GMKAL2H | K26: S2 | L26: 4G | M26: 1800 | N26: AQU4518R9v06 | O26: 70 | P26: 165 | R26: 0 | Y26: =_xlfn.XLOOKUP(H26,'[1]4G Parameters'!$G:$G,'[1]4G Parameters'!$AA:$AA) | Z26: 6T6R | AA26: 4TR | AB26: R9264H M901821 | AC26: A9652 S35*3+R9264H M901821*4+R9254E S8500*2+FL8590A*4 | AD26: AQU4518R9v06 | AE26: 70 | AF26: 165 | AH26: 0 | AI26: =_xlfn.XLOOKUP(A26,'[2]177+10+50 Sites (detail)'!$B:$B,'[2]177+10+50 Sites (detail)'!$I:$I) | AJ26: =_xlfn.XLOOKUP(A26,[3]最小距离站点!$A:$A,[3]最小距离站点!$B:$B) | AK26: =_xlfn.XLOOKUP(A26,[3]最小距离站点!$A:$A,[3]最小距离站点!$C:$C) | AL26: pilot'
A27: GMKAL2 | B27: GMKAL2_GUL00_Kalagedihena_Gm | C27: Huawei | F27: 7.117603 | G27: 80.06068 | H27: GMKAL2-M-L85-B1 | K27: S2 | L27: 4G | M27: 850 | N27: AQU4518R9v06 | O27: 70 | P27: 165 | R27: 0 | Y27: =_xlfn.XLOOKUP(H27,'[1]4G Parameters'!$G:$G,'[1]4G Parameters'!$AA:$AA) | Z27: 2T2R | AA27: 2T2R | AB27: R9254E S8500 | AC27: A9652 S35*3+R9264H M901821*4+R9254E S8500*2+FL8590A*4 | AD27: AQU4518R9v06 | AE27: 70 | AF27: 165 | AH27: 0 | AI27: =_xlfn.XLOOKUP(A27,'[2]177+10+50 Sites (detail)'!$B:$B,'[2]177+10+50 Sites (detail)'!$I:$I) | AJ27: =_xlfn.XLOOKUP(A27,[3]最小距离站点!$A:$A,[3]最小距离站点!$B:$B) | AK27: =_xlfn.XLOOKUP(A27,[3]最小距离站点!$A:$A,[3]最小距离站点!$C:$C) | AL27: pilot'
A28: GMKAL2 | B28: GMKAL2_GUL00_Kalagedihena_Gm | C28: Huawei | F28: 7.117603 | G28: 80.06068 | H28: GMKAL2-M-L21-C2 | K28: S3 | L28: 4G | M28: 2100 | N28: AQU4518R9v06 | O28: 70 | P28: 220 | R28: 0 | Y28: =_xlfn.XLOOKUP(H28,'[1]4G Parameters'!$G:$G,'[1]4G Parameters'!$AA:$AA) | Z28: 6T6R | AA28: 4TR | AB28: R9264H M901821 | AC28: A9652 S35*3+R9264H M901821*4+R9254E S8500*2+FL8590A*4 | AD28: AQU4518R9v06 | AE28: 70 | AF28: 220 | AH28: 0 | AI28: =_xlfn.XLOOKUP(A28,'[2]177+10+50 Sites (detail)'!$B:$B,'[2]177+10+50 Sites (detail)'!$I:$I) | AJ28: =_xlfn.XLOOKUP(A28,[3]最小距离站点!$A:$A,[3]最小距离站点!$B:$B) | AK28: =_xlfn.XLOOKUP(A28,[3]最小距离站点!$A:$A,[3]最小距离站点!$C:$C) | AL28: pilot'
A29: GMKAL2 | B29: GMKAL2_GUL00_Kalagedihena_Gm | C29: Huawei | F29: 7.117603 | G29: 80.06068 | H29: GMKAL2I | K29: S3 | L29: 4G | M29: 1800 | N29: AQU4518R9v06 | O29: 70 | P29: 220 | R29: 0 | Y29: =_xlfn.XLOOKUP(H29,'[1]4G Parameters'!$G:$G,'[1]4G Parameters'!$AA:$AA) | Z29: 6T6R | AA29: 4TR | AB29: R9264H M901821 | AC29: A9652 S35*3+R9264H M901821*4+R9254E S8500*2+FL8590A*4 | AD29: AQU4518R9v06 | AE29: 70 | AF29: 220 | AH29: 0 | AI29: =_xlfn.XLOOKUP(A29,'[2]177+10+50 Sites (detail)'!$B:$B,'[2]177+10+50 Sites (detail)'!$I:$I) | AJ29: =_xlfn.XLOOKUP(A29,[3]最小距离站点!$A:$A,[3]最小距离站点!$B:$B) | AK29: =_xlfn.XLOOKUP(A29,[3]最小距离站点!$A:$A,[3]最小距离站点!$C:$C) | AL29: pilot'
A30: GMKAL2 | B30: GMKAL2_GUL00_Kalagedihena_Gm | C30: Huawei | F30: 7.117603 | G30: 80.06068 | H30: GMKAL2-M-L85-C1 | K30: S3 | L30: 4G | M30: 850 | N30: AQU4518R9v06 | O30: 70 | P30: 220 | R30: 0 | Y30: =_xlfn.XLOOKUP(H30,'[1]4G Parameters'!$G:$G,'[1]4G Parameters'!$AA:$AA) | Z30: 2T2R | AA30: 2T2R | AB30: R9254E S8500 | AC30: A9652 S35*3+R9264H M901821*4+R9254E S8500*2+FL8590A*4 | AD30: AQU4518R9v06 | AE30: 70 | AF30: 220 | AH30: 0 | AI30: =_xlfn.XLOOKUP(A30,'[2]177+10+50 Sites (detail)'!$B:$B,'[2]177+10+50 Sites (detail)'!$I:$I) | AJ30: =_xlfn.XLOOKUP(A30,[3]最小距离站点!$A:$A,[3]最小距离站点!$B:$B) | AK30: =_xlfn.XLOOKUP(A30,[3]最小距离站点!$A:$A,[3]最小距离站点!$C:$C) | AL30: pilot'
A31: GMKAL2 | B31: GMKAL2_GUL00_Kalagedihena_Gm | C31: Huawei | F31: 7.117603 | G31: 80.06068 | H31: GMKAL2-M-L21-D2 | K31: S4 | L31: 4G | M31: 2100 | N31: AQU4518R9v06 | O31: 70 | P31: 285 | R31: 0 | Y31: =_xlfn.XLOOKUP(H31,'[1]4G Parameters'!$G:$G,'[1]4G Parameters'!$AA:$AA) | Z31: 6T6R | AA31: 4TR | AB31: R9264H M901821 | AC31: A9652 S35*3+R9264H M901821*4+R9254E S8500*2+FL8590A*4 | AD31: AQU4518R9v06 | AE31: 70 | AF31: 285 | AH31: 0 | AI31: =_xlfn.XLOOKUP(A31,'[2]177+10+50 Sites (detail)'!$B:$B,'[2]177+10+50 Sites (detail)'!$I:$I) | AJ31: =_xlfn.XLOOKUP(A31,[3]最小距离站点!$A:$A,[3]最小距离站点!$B:$B) | AK31: =_xlfn.XLOOKUP(A31,[3]最小距离站点!$A:$A,[3]最小距离站点!$C:$C) | AL31: pilot'
A32: GMKAL2 | B32: GMKAL2_GUL00_Kalagedihena_Gm | C32: Huawei | F32: 7.117603 | G32: 80.06068 | H32: GMKAL2F | K32: S4 | L32: 4G | M32: 1800 | N32: AQU4518R9v06 | O32: 70 | P32: 285 | R32: 0 | Y32: =_xlfn.XLOOKUP(H32,'[1]4G Parameters'!$G:$G,'[1]4G Parameters'!$AA:$AA) | Z32: 6T6R | AA32: 4TR | AB32: R9264H M901821 | AC32: A9652 S35*3+R9264H M901821*4+R9254E S8500*2+FL8590A*4 | AD32: AQU4518R9v06 | AE32: 70 | AF32: 285 | AH32: 0 | AI32: =_xlfn.XLOOKUP(A32,'[2]177+10+50 Sites (detail)'!$B:$B,'[2]177+10+50 Sites (detail)'!$I:$I) | AJ32: =_xlfn.XLOOKUP(A32,[3]最小距离站点!$A:$A,[3]最小距离站点!$B:$B) | AK32: =_xlfn.XLOOKUP(A32,[3]最小距离站点!$A:$A,[3]最小距离站点!$C:$C) | AL32: pilot'
A33: GMKAL2 | B33: GMKAL2_GUL00_Kalagedihena_Gm | C33: Huawei | F33: 7.117603 | G33: 80.06068 | H33: GMKAL2-M-L85-D1 | K33: S4 | L33: 4G | M33: 850 | N33: AQU4518R9v06 | O33: 70 | P33: 285 | R33: 0 | Y33: =_xlfn.XLOOKUP(H33,'[1]4G Parameters'!$G:$G,'[1]4G Parameters'!$AA:$AA) | Z33: 2T2R | AA33: 2T2R | AB33: R9254E S8500 | AC33: A9652 S35*3+R9264H M901821*4+R9254E S8500*2+FL8590A*4 | AD33: AQU4518R9v06 | AE33: 70 | AF33: 285 | AH33: 0 | AI33: =_xlfn.XLOOKUP(A33,'[2]177+10+50 Sites (detail)'!$B:$B,'[2]177+10+50 Sites (detail)'!$I:$I) | AJ33: =_xlfn.XLOOKUP(A33,[3]最小距离站点!$A:$A,[3]最小距离站点!$B:$B) | AK33: =_xlfn.XLOOKUP(A33,[3]最小距离站点!$A:$A,[3]最小距离站点!$C:$C) | AL33: pilot'
A34: GMMAG1 | B34: GMMAG1_G_Magalegoda__89__Gm | C34: Huawei | F34: 7.13739 | G34: 80.04 | H34: GMMAG1P | K34: S1 | L34: 2G | M34: 1800 | N34: AQU4518R9v06 | O34: 60 | P34: 45 | R34: 2 | AA34: 1T1R | AB34: R9264H M901821 | AC34: A9652 S35*3+R9264H M901821*3+R9254E S8500*2+R9264 M1821N*2+FL8590A*3 | AD34: AQU4518R9v06 | AE34: 60 | AF34: 45 | AH34: 2 | AL34: pilot'
A35: GMMAG1 | B35: GMMAG1_G_Magalegoda__89__Gm | C35: Huawei | F35: 7.13739 | G35: 80.04 | H35: GMMAG1A | K35: S1 | L35: 2G | M35: 900 | N35: AQU4518R9v06 | O35: 60 | P35: 45 | R35: 2 | AA35: 1T1R | AB35: R9264H M901821 | AC35: A9652 S35*3+R9264H M901821*3+R9254E S8500*2+R9264 M1821N*2+FL8590A*3 | AD35: AQU4518R9v06 | AE35: 60 | AF35: 45 | AH35: 2 | AL35: pilot'
A36: GMMAG1 | B36: GMMAG1_G_Magalegoda__89__Gm | C36: Huawei | F36: 7.13739 | G36: 80.04 | H36: GMMAG1Q | K36: S2 | L36: 2G | M36: 1800 | N36: AQU4518R9v06 | O36: 60 | P36: 150 | R36: 2 | AA36: 1T1R | AB36: R9264H M901821 | AC36: A9652 S35*3+R9264H M901821*3+R9254E S8500*2+R9264 M1821N*2+FL8590A*3 | AD36: AQU4518R9v06 | AE36: 60 | AF36: 150 | AH36: 2 | AL36: pilot'
A37: GMMAG1 | B37: GMMAG1_G_Magalegoda__89__Gm | C37: Huawei | F37: 7.13739 | G37: 80.04 | H37: GMMAG1B | K37: S2 | L37: 2G | M37: 900 | N37: AQU4518R9v06 | O37: 60 | P37: 150 | R37: 2 | AA37: 1T1R | AB37: R9264H M901821 | AC37: A9652 S35*3+R9264H M901821*3+R9254E S8500*2+R9264 M1821N*2+FL8590A*3 | AD37: AQU4518R9v06 | AE37: 60 | AF37: 150 | AH37: 2 | AL37: pilot'
A38: GMMAG1 | B38: GMMAG1_G_Magalegoda__89__Gm | C38: Huawei | F38: 7.13739 | G38: 80.04 | H38: GMMAG1R | K38: S3 | L38: 2G | M38: 1800 | N38: AQU4518R9v06 | O38: 60 | P38: 335 | R38: 2 | AA38: 1T1R | AB38: R9264H M901821 | AC38: A9652 S35*3+R9264H M901821*3+R9254E S8500*2+R9264 M1821N*2+FL8590A*3 | AD38: AQU4518R9v06 | AE38: 60 | AF38: 335 | AH38: 2 | AL38: pilot'
A39: GMMAG1 | B39: GMMAG1_G_Magalegoda__89__Gm | C39: Huawei | F39: 7.13739 | G39: 80.04 | H39: GMMAG1C | K39: S3 | L39: 2G | M39: 900 | N39: AQU4518R9v06 | O39: 60 | P39: 335 | R39: 2 | AA39: 1T1R | AB39: R9264H M901821 | AC39: A9652 S35*3+R9264H M901821*3+R9254E S8500*2+R9264 M1821N*2+FL8590A*3 | AD39: AQU4518R9v06 | AE39: 60 | AF39: 335 | AH39: 2 | AL39: pilot'
A40: GMMAG1 | B40: GMMAG1_GUL00_Magalegoda_Gm | C40: Huawei | F40: 7.13739 | G40: 80.04 | H40: GMMAG1-M-L21-A2 | K40: S1 | L40: 4G | M40: 2100 | N40: AQU4518R9v06 | O40: 60 | P40: 45 | R40: 0 | Y40: =_xlfn.XLOOKUP(H40,'[1]4G Parameters'!$G:$G,'[1]4G Parameters'!$AA:$AA) | Z40: 6T6R | AA40: 4T4R | AB40: R9264H M901821 | AC40: A9652 S35*3+R9264H M901821*3+R9254E S8500*2+R9264 M1821N*2+FL8590A*3 | AD40: AQU4518R9v06 | AE40: 60 | AF40: 45 | AH40: 0 | AI40: =_xlfn.XLOOKUP(A40,'[2]177+10+50 Sites (detail)'!$B:$B,'[2]177+10+50 Sites (detail)'!$I:$I) | AJ40: =_xlfn.XLOOKUP(A40,[3]最小距离站点!$A:$A,[3]最小距离站点!$B:$B) | AK40: =_xlfn.XLOOKUP(A40,[3]最小距离站点!$A:$A,[3]最小距离站点!$C:$C) | AL40: pilot'
...

Sheet 2G
A1: Cell Name | B1: Site Name | C1: Sector ID | D1: RRU Type | E1: TX/RX mode | F1: Band | G1: NE Name | H1: BTS Name | I1: Site ID | J1: CI | K1: BSC Name | L1: BSC ID | M1: MCC | N1: MNC | O1: NCC | P1: BCC | Q1: BSIC | R1: BCCH | S1: LAC | T1: RAC | U1: Band | V1: Total TRX | W1: TRX Power(W) | X1: Hop Type | Y1: HSN | Z1: TCH/MAList | AA1: MAIO
A2: 01208171_IC_Pisco | B2: =_xlfn.XLOOKUP(A2,'RF Parameter'!I:I,'RF Parameter'!A:A) | C2: =_xlfn.XLOOKUP(A2,'RF Parameter'!I:I,'RF Parameter'!K:K) | D2: =_xlfn.XLOOKUP(A2,'RF Parameter'!I:I,'RF Parameter'!AB:AB) | E2: =_xlfn.XLOOKUP(A2,'RF Parameter'!I:I,'RF Parameter'!AA:AA) | F2: =_xlfn.XLOOKUP(A2,'RF Parameter'!I:I,'RF Parameter'!M:M) | G2: =_xlfn.XLOOKUP(A2,'RF Parameter'!I:I,'RF Parameter'!B:B) | H2: 0120817_IC_Pisco | I2: 817 | J2: 8171 | M2: 716 | N2: 17 | O2: 5 | P2: 1 | Q2: =O2&P2 | R2: 731 | S2: 25652 | T2: 98 | U2: G1900 | V2: 1 | W2: 20 | X2: NO_FH | Y2: - | Z2: - | AA2: -
A3: 01208172_IC_Pisco | B3: =_xlfn.XLOOKUP(A3,'RF Parameter'!I:I,'RF Parameter'!A:A) | C3: =_xlfn.XLOOKUP(A3,'RF Parameter'!I:I,'RF Parameter'!K:K) | D3: =_xlfn.XLOOKUP(A3,'RF Parameter'!I:I,'RF Parameter'!AB:AB) | E3: =_xlfn.XLOOKUP(A3,'RF Parameter'!I:I,'RF Parameter'!AA:AA) | F3: =_xlfn.XLOOKUP(A3,'RF Parameter'!I:I,'RF Parameter'!M:M) | G3: =_xlfn.XLOOKUP(A3,'RF Parameter'!I:I,'RF Parameter'!B:B) | H3: 0120817_IC_Pisco | I3: 817 | J3: 8172 | M3: 716 | N3: 17 | O3: 0 | P3: 3 | Q3: =O3&P3 | R3: 735 | S3: 25652 | T3: 98 | U3: G1900 | V3: 1 | W3: 15 | X3: NO_FH | Y3: - | Z3: - | AA3: -
A4: 01208173_IC_Pisco | B4: =_xlfn.XLOOKUP(A4,'RF Parameter'!I:I,'RF Parameter'!A:A) | C4: =_xlfn.XLOOKUP(A4,'RF Parameter'!I:I,'RF Parameter'!K:K) | D4: =_xlfn.XLOOKUP(A4,'RF Parameter'!I:I,'RF Parameter'!AB:AB) | E4: =_xlfn.XLOOKUP(A4,'RF Parameter'!I:I,'RF Parameter'!AA:AA) | F4: =_xlfn.XLOOKUP(A4,'RF Parameter'!I:I,'RF Parameter'!M:M) | G4: =_xlfn.XLOOKUP(A4,'RF Parameter'!I:I,'RF Parameter'!B:B) | H4: 0120817_IC_Pisco | I4: 817 | J4: 8173 | M4: 716 | N4: 17 | O4: 6 | P4: 0 | Q4: =O4&P4 | R4: 587 | S4: 25652 | T4: 98 | U4: G1900 | V4: 1 | W4: 20 | X4: NO_FH | Y4: - | Z4: - | AA4: -
A5: 01222541_IC_Garzas_Mir_1900 | B5: =_xlfn.XLOOKUP(A5,'RF Parameter'!I:I,'RF Parameter'!A:A) | C5: =_xlfn.XLOOKUP(A5,'RF Parameter'!I:I,'RF Parameter'!K:K) | D5: =_xlfn.XLOOKUP(A5,'RF Parameter'!I:I,'RF Parameter'!AB:AB) | E5: =_xlfn.XLOOKUP(A5,'RF Parameter'!I:I,'RF Parameter'!AA:AA) | F5: =_xlfn.XLOOKUP(A5,'RF Parameter'!I:I,'RF Parameter'!M:M) | G5: =_xlfn.XLOOKUP(A5,'RF Parameter'!I:I,'RF Parameter'!B:B) | H5: 0122254_IC_Garzas_Mir_1900 | I5: 2254 | J5: 22541 | M5: 716 | N5: 17 | O5: 5 | P5: 2 | Q5: =O5&P5 | R5: 732 | S5: 25652 | T5: 98 | U5: G1900 | V5: 1 | W5: 20 | X5: NO_FH | Y5: - | Z5: - | AA5: -
A6: 01222542_IC_Garzas_Mir_1900 | B6: =_xlfn.XLOOKUP(A6,'RF Parameter'!I:I,'RF Parameter'!A:A) | C6: =_xlfn.XLOOKUP(A6,'RF Parameter'!I:I,'RF Parameter'!K:K) | D6: =_xlfn.XLOOKUP(A6,'RF Parameter'!I:I,'RF Parameter'!AB:AB) | E6: =_xlfn.XLOOKUP(A6,'RF Parameter'!I:I,'RF Parameter'!AA:AA) | F6: =_xlfn.XLOOKUP(A6,'RF Parameter'!I:I,'RF Parameter'!M:M) | G6: =_xlfn.XLOOKUP(A6,'RF Parameter'!I:I,'RF Parameter'!B:B) | H6: 0122254_IC_Garzas_Mir_1900 | I6: 2254 | J6: 22542 | M6: 716 | N6: 17 | O6: 4 | P6: 7 | Q6: =O6&P6 | R6: 679 | S6: 25652 | T6: 98 | U6: G1900 | V6: 1 | W6: 20 | X6: NO_FH | Y6: - | Z6: - | AA6: -
A7: 01222543_IC_Garzas_Mir_1900 | B7: =_xlfn.XLOOKUP(A7,'RF Parameter'!I:I,'RF Parameter'!A:A) | C7: =_xlfn.XLOOKUP(A7,'RF Parameter'!I:I,'RF Parameter'!K:K) | D7: =_xlfn.XLOOKUP(A7,'RF Parameter'!I:I,'RF Parameter'!AB:AB) | E7: =_xlfn.XLOOKUP(A7,'RF Parameter'!I:I,'RF Parameter'!AA:AA) | F7: =_xlfn.XLOOKUP(A7,'RF Parameter'!I:I,'RF Parameter'!M:M) | G7: =_xlfn.XLOOKUP(A7,'RF Parameter'!I:I,'RF Parameter'!B:B) | H7: 0122254_IC_Garzas_Mir_1900 | I7: 2254 | J7: 22543 | M7: 716 | N7: 17 | O7: 2 | P7: 3 | Q7: =O7&P7 | R7: 675 | S7: 25652 | T7: 98 | U7: G1900 | V7: 1 | W7: 20 | X7: NO_FH | Y7: - | Z7: - | AA7: -
A8: 01222471_IC_San_Clemente | B8: =_xlfn.XLOOKUP(A8,'RF Parameter'!I:I,'RF Parameter'!A:A) | C8: =_xlfn.XLOOKUP(A8,'RF Parameter'!I:I,'RF Parameter'!K:K) | D8: =_xlfn.XLOOKUP(A8,'RF Parameter'!I:I,'RF Parameter'!AB:AB) | E8: =_xlfn.XLOOKUP(A8,'RF Parameter'!I:I,'RF Parameter'!AA:AA) | F8: =_xlfn.XLOOKUP(A8,'RF Parameter'!I:I,'RF Parameter'!M:M) | G8: =_xlfn.XLOOKUP(A8,'RF Parameter'!I:I,'RF Parameter'!B:B) | H8: 0122247_IC_San_Clemente | I8: 2247 | J8: 22471 | M8: 716 | N8: 17 | O8: 6 | P8: 5 | Q8: =O8&P8 | R8: 677 | S8: 25652 | T8: 98 | U8: G1900 | V8: 1 | W8: 15 | X8: NO_FH | Y8: - | Z8: - | AA8: -
A9: 01222472_IC_San_Clemente | B9: =_xlfn.XLOOKUP(A9,'RF Parameter'!I:I,'RF Parameter'!A:A) | C9: =_xlfn.XLOOKUP(A9,'RF Parameter'!I:I,'RF Parameter'!K:K) | D9: =_xlfn.XLOOKUP(A9,'RF Parameter'!I:I,'RF Parameter'!AB:AB) | E9: =_xlfn.XLOOKUP(A9,'RF Parameter'!I:I,'RF Parameter'!AA:AA) | F9: =_xlfn.XLOOKUP(A9,'RF Parameter'!I:I,'RF Parameter'!M:M) | G9: =_xlfn.XLOOKUP(A9,'RF Parameter'!I:I,'RF Parameter'!B:B) | H9: 0122247_IC_San_Clemente | I9: 2247 | J9: 22472 | M9: 716 | N9: 17 | O9: 5 | P9: 3 | Q9: =O9&P9 | R9: 734 | S9: 25652 | T9: 98 | U9: G1900 | V9: 1 | W9: 15 | X9: NO_FH | Y9: - | Z9: - | AA9: -
A10: 01222473_IC_San_Clemente | B10: =_xlfn.XLOOKUP(A10,'RF Parameter'!I:I,'RF Parameter'!A:A) | C10: =_xlfn.XLOOKUP(A10,'RF Parameter'!I:I,'RF Parameter'!K:K) | D10: =_xlfn.XLOOKUP(A10,'RF Parameter'!I:I,'RF Parameter'!AB:AB) | E10: =_xlfn.XLOOKUP(A10,'RF Parameter'!I:I,'RF Parameter'!AA:AA) | F10: =_xlfn.XLOOKUP(A10,'RF Parameter'!I:I,'RF Parameter'!M:M) | G10: =_xlfn.XLOOKUP(A10,'RF Parameter'!I:I,'RF Parameter'!B:B) | H10: 0122247_IC_San_Clemente | I10: 2247 | J10: 22473 | M10: 716 | N10: 17 | O10: 0 | P10: 6 | Q10: =O10&P10 | R10: 674 | S10: 25652 | T10: 98 | U10: G1900 | V10: 1 | W10: 15 | X10: NO_FH | Y10: - | Z10: - | AA10: -
A11: 01246821_IC_Clemente_Bajo | B11: =_xlfn.XLOOKUP(A11,'RF Parameter'!I:I,'RF Parameter'!A:A) | C11: =_xlfn.XLOOKUP(A11,'RF Parameter'!I:I,'RF Parameter'!K:K) | D11: =_xlfn.XLOOKUP(A11,'RF Parameter'!I:I,'RF Parameter'!AB:AB) | E11: =_xlfn.XLOOKUP(A11,'RF Parameter'!I:I,'RF Parameter'!AA:AA) | F11: =_xlfn.XLOOKUP(A11,'RF Parameter'!I:I,'RF Parameter'!M:M) | G11: =_xlfn.XLOOKUP(A11,'RF Parameter'!I:I,'RF Parameter'!B:B) | H11: 0124682_IC_Clemente_Bajo | I11: 4682 | J11: 46821 | M11: 716 | N11: 17 | O11: 6 | P11: 4 | Q11: =O11&P11 | R11: 733 | S11: 25652 | T11: 98 | U11: G1900 | V11: 1 | W11: 15 | X11: NO_FH | Y11: - | Z11: - | AA11: -
A12: 01246822_IC_Clemente_Bajo | B12: =_xlfn.XLOOKUP(A12,'RF Parameter'!I:I,'RF Parameter'!A:A) | C12: =_xlfn.XLOOKUP(A12,'RF Parameter'!I:I,'RF Parameter'!K:K) | D12: =_xlfn.XLOOKUP(A12,'RF Parameter'!I:I,'RF Parameter'!AB:AB) | E12: =_xlfn.XLOOKUP(A12,'RF Parameter'!I:I,'RF Parameter'!AA:AA) | F12: =_xlfn.XLOOKUP(A12,'RF Parameter'!I:I,'RF Parameter'!M:M) | G12: =_xlfn.XLOOKUP(A12,'RF Parameter'!I:I,'RF Parameter'!B:B) | H12: 0124682_IC_Clemente_Bajo | I12: 4682 | J12: 46822 | M12: 716 | N12: 17 | O12: 7 | P12: 0 | Q12: =O12&P12 | R12: 679 | S12: 25652 | T12: 98 | U12: G1900 | V12: 1 | W12: 15 | X12: NO_FH | Y12: - | Z12: - | AA12: -
A13: 01246823_IC_Clemente_Bajo | B13: =_xlfn.XLOOKUP(A13,'RF Parameter'!I:I,'RF Parameter'!A:A) | C13: =_xlfn.XLOOKUP(A13,'RF Parameter'!I:I,'RF Parameter'!K:K) | D13: =_xlfn.XLOOKUP(A13,'RF Parameter'!I:I,'RF Parameter'!AB:AB) | E13: =_xlfn.XLOOKUP(A13,'RF Parameter'!I:I,'RF Parameter'!AA:AA) | F13: =_xlfn.XLOOKUP(A13,'RF Parameter'!I:I,'RF Parameter'!M:M) | G13: =_xlfn.XLOOKUP(A13,'RF Parameter'!I:I,'RF Parameter'!B:B) | H13: 0124682_IC_Clemente_Bajo | I13: 4682 | J13: 46823 | M13: 716 | N13: 17 | O13: 2 | P13: 6 | Q13: =O13&P13 | R13: 735 | S13: 25652 | T13: 98 | U13: G1900 | V13: 1 | W13: 15 | X13: NO_FH | Y13: - | Z13: - | AA13: -
... A16: 01246913_IC_Villa_Amaru | B16: =_xlfn.XLOOKUP(A16,'RF Parameter'!I:I,'RF Parameter'!A:A) | C16: =_xlfn.XLOOKUP(A16,'RF Parameter'!I:I,'RF Parameter'!K:K) | D16: =_xlfn.XLOOKUP(A16,'RF Parameter'!I:I,'RF Parameter'!AB:AB) | E16: =_xlfn.XLOOKUP(A16,'RF Parameter'!I:I,'RF Parameter'!AA:AA) | F16: =_xlfn.XLOOKUP(A16,'RF Parameter'!I:I,'RF Parameter'!M:M) | G16: =_xlfn.XLOOKUP(A16,'RF Parameter'!I:I,'RF Parameter'!B:B) | H16: 0124691_IC_Villa_Amaru | I16: 4691 | J16: 46913 | M16: 716 | N16: 17 | O16: 0 | P16: 3 | Q16: =O16&P16 | R16: 675 | S16: 25652 | T16: 98 | U16: G1900 | V16: 1 | W16: 15 | X16: NO_FH | Y16: - | Z16: - | AA16: -

Sheet 3G
A1: Cell Name | B1: Site Name | C1: Sector ID | D1: RRU Type | E1: TX/RX mode | F1: Band | G1: NE Name | H1: NodeB Name | I1: RNC Name | J1: RNC ID | K1: Nodeb ID | L1: CI | M1: MORAN | N1: MCC | O1: MNC | P1: PSC | Q1: LAC | R1: RAC | S1: URA | T1: SAC | U1: Cell Power(W) | V1: Cell Power(dBm) | W1: Pilot Power(dBm) | X1: DL Center Frequency | Y1: UL Center Frequency | Z1: DL UARFCN | AA1: UL UARFCN | AB1: Bandwidth
A2: 01308171_IC_Pisco | B2: =_xlfn.XLOOKUP(A2,'RF Parameter'!I:I,'RF Parameter'!A:A) | C2: =_xlfn.XLOOKUP(A2,'RF Parameter'!I:I,'RF Parameter'!K:K) | D2: =_xlfn.XLOOKUP(A2,'RF Parameter'!I:I,'RF Parameter'!AB:AB) | E2: =_xlfn.XLOOKUP(A2,'RF Parameter'!I:I,'RF Parameter'!AA:AA) | F2: =_xlfn.XLOOKUP(A2,'RF Parameter'!I:I,'RF Parameter'!M:M) | G2: =_xlfn.XLOOKUP(A2,'RF Parameter'!I:I,'RF Parameter'!B:B) | H2: =G2 | K2: 817 | L2: 8171 | M2: No | N2: 716 | O2: 17 | P2: 0 | Q2: 35652 | R2: 108 | S2: 106 | T2: 8171 | U2: 30 | V2: 44.7 | W2: 34.7 | X2: =Z2/5+1850.1 | Y2: =AA2/5+1850.1 | Z2: 487 | AA2: 87 | AB2: 5M
A3: 01308172_IC_Pisco | B3: =_xlfn.XLOOKUP(A3,'RF Parameter'!I:I,'RF Parameter'!A:A) | C3: =_xlfn.XLOOKUP(A3,'RF Parameter'!I:I,'RF Parameter'!K:K) | D3: =_xlfn.XLOOKUP(A3,'RF Parameter'!I:I,'RF Parameter'!AB:AB) | E3: =_xlfn.XLOOKUP(A3,'RF Parameter'!I:I,'RF Parameter'!AA:AA) | F3: =_xlfn.XLOOKUP(A3,'RF Parameter'!I:I,'RF Parameter'!M:M) | G3: =_xlfn.XLOOKUP(A3,'RF Parameter'!I:I,'RF Parameter'!B:B) | H3: =G3 | K3: 817 | L3: 8172 | M3: No | N3: 716 | O3: 17 | P3: 44 | Q3: 35652 | R3: 108 | S3: 106 | T3: 8172 | U3: 40 | V3: 46 | W3: 36 | X3: =Z3/5+1850.1 | Y3: =AA3/5+1850.1 | Z3: 487 | AA3: 87 | AB3: 5M
A4: 01308173_IC_Pisco | B4: =_xlfn.XLOOKUP(A4,'RF Parameter'!I:I,'RF Parameter'!A:A) | C4: =_xlfn.XLOOKUP(A4,'RF Parameter'!I:I,'RF Parameter'!K:K) | D4: =_xlfn.XLOOKUP(A4,'RF Parameter'!I:I,'RF Parameter'!AB:AB) | E4: =_xlfn.XLOOKUP(A4,'RF Parameter'!I:I,'RF Parameter'!AA:AA) | F4: =_xlfn.XLOOKUP(A4,'RF Parameter'!I:I,'RF Parameter'!M:M) | G4: =_xlfn.XLOOKUP(A4,'RF Parameter'!I:I,'RF Parameter'!B:B) | H4: =G4 | K4: 817 | L4: 8173 | M4: No | N4: 716 | O4: 17 | P4: 45 | Q4: 35652 | R4: 108 | S4: 106 | T4: 8173 | U4: 40 | V4: 46 | W4: 36 | X4: =Z4/5+1850.1 | Y4: =AA4/5+1850.1 | Z4: 487 | AA4: 87 | AB4: 5M
A5: 01322471_IC_San_Clemente | B5: =_xlfn.XLOOKUP(A5,'RF Parameter'!I:I,'RF Parameter'!A:A) | C5: =_xlfn.XLOOKUP(A5,'RF Parameter'!I:I,'RF Parameter'!K:K) | D5: =_xlfn.XLOOKUP(A5,'RF Parameter'!I:I,'RF Parameter'!AB:AB) | E5: =_xlfn.XLOOKUP(A5,'RF Parameter'!I:I,'RF Parameter'!AA:AA) | F5: =_xlfn.XLOOKUP(A5,'RF Parameter'!I:I,'RF Parameter'!M:M) | G5: =_xlfn.XLOOKUP(A5,'RF Parameter'!I:I,'RF Parameter'!B:B) | H5: =G5 | K5: 2247 | L5: 22471 | M5: No | N5: 716 | O5: 17 | P5: 360 | Q5: 35652 | R5: 108 | S5: 106 | T5: 22471 | U5: 30 | V5: 44.7 | W5: 36 | X5: =Z5/5+1850.1 | Y5: =AA5/5+1850.1 | Z5: 487 | AA5: 87 | AB5: 5M
A6: 01322472_IC_San_Clemente | B6: =_xlfn.XLOOKUP(A6,'RF Parameter'!I:I,'RF Parameter'!A:A) | C6: =_xlfn.XLOOKUP(A6,'RF Parameter'!I:I,'RF Parameter'!K:K) | D6: =_xlfn.XLOOKUP(A6,'RF Parameter'!I:I,'RF Parameter'!AB:AB) | E6: =_xlfn.XLOOKUP(A6,'RF Parameter'!I:I,'RF Parameter'!AA:AA) | F6: =_xlfn.XLOOKUP(A6,'RF Parameter'!I:I,'RF Parameter'!M:M) | G6: =_xlfn.XLOOKUP(A6,'RF Parameter'!I:I,'RF Parameter'!B:B) | H6: =G6 | K6: 2247 | L6: 22472 | M6: No | N6: 716 | O6: 17 | P6: 361 | Q6: 35652 | R6: 108 | S6: 106 | T6: 22472 | U6: 49 | V6: 46.9 | W6: 36 | X6: =Z6/5+1850.1 | Y6: =AA6/5+1850.1 | Z6: 487 | AA6: 87 | AB6: 5M
A7: 01322473_IC_San_Clemente | B7: =_xlfn.XLOOKUP(A7,'RF Parameter'!I:I,'RF Parameter'!A:A) | C7: =_xlfn.XLOOKUP(A7,'RF Parameter'!I:I,'RF Parameter'!K:K) | D7: =_xlfn.XLOOKUP(A7,'RF Parameter'!I:I,'RF Parameter'!AB:AB) | E7: =_xlfn.XLOOKUP(A7,'RF Parameter'!I:I,'RF Parameter'!AA:AA) | F7: =_xlfn.XLOOKUP(A7,'RF Parameter'!I:I,'RF Parameter'!M:M) | G7: =_xlfn.XLOOKUP(A7,'RF Parameter'!I:I,'RF Parameter'!B:B) | H7: =G7 | K7: 2247 | L7: 22473 | M7: No | N7: 716 | O7: 17 | P7: 362 | Q7: 35652 | R7: 108 | S7: 106 | T7: 22473 | U7: 49 | V7: 46.9 | W7: 34.7 | X7: =Z7/5+1850.1 | Y7: =AA7/5+1850.1 | Z7: 487 | AA7: 87 | AB7: 5M
A8: 01322541_IC_Garzas_Mir_1900 | B8: =_xlfn.XLOOKUP(A8,'RF Parameter'!I:I,'RF Parameter'!A:A) | C8: =_xlfn.XLOOKUP(A8,'RF Parameter'!I:I,'RF Parameter'!K:K) | D8: =_xlfn.XLOOKUP(A8,'RF Parameter'!I:I,'RF Parameter'!AB:AB) | E8: =_xlfn.XLOOKUP(A8,'RF Parameter'!I:I,'RF Parameter'!AA:AA) | F8: =_xlfn.XLOOKUP(A8,'RF Parameter'!I:I,'RF Parameter'!M:M) | G8: =_xlfn.XLOOKUP(A8,'RF Parameter'!I:I,'RF Parameter'!B:B) | H8: =G8 | K8: 2254 | L8: 22541 | M8: No | N8: 716 | O8: 17 | P8: 317 | Q8: 35652 | R8: 108 | S8: 106 | T8: 22541 | U8: 30 | V8: 44.7 | W8: 34.7 | X8: =Z8/5+1850.1 | Y8: =AA8/5+1850.1 | Z8: 487 | AA8: 87 | AB8: 5M
A9: 01322542_IC_Garzas_Mir_1900 | B9: =_xlfn.XLOOKUP(A9,'RF Parameter'!I:I,'RF Parameter'!A:A) | C9: =_xlfn.XLOOKUP(A9,'RF Parameter'!I:I,'RF Parameter'!K:K) | D9: =_xlfn.XLOOKUP(A9,'RF Parameter'!I:I,'RF Parameter'!AB:AB) | E9: =_xlfn.XLOOKUP(A9,'RF Parameter'!I:I,'RF Parameter'!AA:AA) | F9: =_xlfn.XLOOKUP(A9,'RF Parameter'!I:I,'RF Parameter'!M:M) | G9: =_xlfn.XLOOKUP(A9,'RF Parameter'!I:I,'RF Parameter'!B:B) | H9: =G9 | K9: 2254 | L9: 22542 | M9: No | N9: 716 | O9: 17 | P9: 318 | Q9: 35652 | R9: 108 | S9: 106 | T9: 22542 | U9: 30 | V9: 44.7 | W9: 34.7 | X9: =Z9/5+1850.1 | Y9: =AA9/5+1850.1 | Z9: 487 | AA9: 87 | AB9: 5M
A10: 01322543_IC_Garzas_Mir_1900 | B10: =_xlfn.XLOOKUP(A10,'RF Parameter'!I:I,'RF Parameter'!A:A) | C10: =_xlfn.XLOOKUP(A10,'RF Parameter'!I:I,'RF Parameter'!K:K) | D10: =_xlfn.XLOOKUP(A10,'RF Parameter'!I:I,'RF Parameter'!AB:AB) | E10: =_xlfn.XLOOKUP(A10,'RF Parameter'!I:I,'RF Parameter'!AA:AA) | F10: =_xlfn.XLOOKUP(A10,'RF Parameter'!I:I,'RF Parameter'!M:M) | G10: =_xlfn.XLOOKUP(A10,'RF Parameter'!I:I,'RF Parameter'!B:B) | H10: =G10 | K10: 2254 | L10: 22543 | M10: No | N10: 716 | O10: 17 | P10: 319 | Q10: 35652 | R10: 108 | S10: 106 | T10: 22543 | U10: 49 | V10: 46.9 | W10: 36.9 | X10: =Z10/5+1850.1 | Y10: =AA10/5+1850.1 | Z10: 487 | AA10: 87 | AB10: 5M
A11: 01346821_IC_Clemente_Bajo | B11: =_xlfn.XLOOKUP(A11,'RF Parameter'!I:I,'RF Parameter'!A:A) | C11: =_xlfn.XLOOKUP(A11,'RF Parameter'!I:I,'RF Parameter'!K:K) | D11: =_xlfn.XLOOKUP(A11,'RF Parameter'!I:I,'RF Parameter'!AB:AB) | E11: =_xlfn.XLOOKUP(A11,'RF Parameter'!I:I,'RF Parameter'!AA:AA) | F11: =_xlfn.XLOOKUP(A11,'RF Parameter'!I:I,'RF Parameter'!M:M) | G11: =_xlfn.XLOOKUP(A11,'RF Parameter'!I:I,'RF Parameter'!B:B) | H11: =G11 | K11: 4682 | L11: 46821 | M11: No | N11: 716 | O11: 17 | P11: 75 | Q11: 35652 | R11: 108 | S11: 106 | T11: 46821 | U11: 20 | V11: 43 | W11: 33 | X11: =Z11/5+1850.1 | Y11: =AA11/5+1850.1 | Z11: 487 | AA11: 87 | AB11: 5M
A12: 01346822_IC_Clemente_Bajo | B12: =_xlfn.XLOOKUP(A12,'RF Parameter'!I:I,'RF Parameter'!A:A) | C12: =_xlfn.XLOOKUP(A12,'RF Parameter'!I:I,'RF Parameter'!K:K) | D12: =_xlfn.XLOOKUP(A12,'RF Parameter'!I:I,'RF Parameter'!AB:AB) | E12: =_xlfn.XLOOKUP(A12,'RF Parameter'!I:I,'RF Parameter'!AA:AA) | F12: =_xlfn.XLOOKUP(A12,'RF Parameter'!I:I,'RF Parameter'!M:M) | G12: =_xlfn.XLOOKUP(A12,'RF Parameter'!I:I,'RF Parameter'!B:B) | H12: =G12 | K12: 4682 | L12: 46822 | M12: No | N12: 716 | O12: 17 | P12: 76 | Q12: 35652 | R12: 108 | S12: 106 | T12: 46822 | U12: 20 | V12: 43 | W12: 33 | X12: =Z12/5+1850.1 | Y12: =AA12/5+1850.1 | Z12: 487 | AA12: 87 | AB12: 5M
A13: 01346823_IC_Clemente_Bajo | B13: =_xlfn.XLOOKUP(A13,'RF Parameter'!I:I,'RF Parameter'!A:A) | C13: =_xlfn.XLOOKUP(A13,'RF Parameter'!I:I,'RF Parameter'!K:K) | D13: =_xlfn.XLOOKUP(A13,'RF Parameter'!I:I,'RF Parameter'!AB:AB) | E13: =_xlfn.XLOOKUP(A13,'RF Parameter'!I:I,'RF Parameter'!AA:AA) | F13: =_xlfn.XLOOKUP(A13,'RF Parameter'!I:I,'RF Parameter'!M:M) | G13: =_xlfn.XLOOKUP(A13,'RF Parameter'!I:I,'RF Parameter'!B:B) | H13: =G13 | K13: 4682 | L13: 46823 | M13: No | N13: 716 | O13: 17 | P13: 77 | Q13: 35652 | R13: 108 | S13: 106 | T13: 46823 | U13: 20 | V13: 43 | W13: 33 | X13: =Z13/5+1850.1 | Y13: =AA13/5+1850.1 | Z13: 487 | AA13: 87 | AB13: 5M
... A16: 01346913_IC_Villa_Amaru | B16: =_xlfn.XLOOKUP(A16,'RF Parameter'!I:I,'RF Parameter'!A:A) | C16: =_xlfn.XLOOKUP(A16,'RF Parameter'!I:I,'RF Parameter'!K:K) | D16: =_xlfn.XLOOKUP(A16,'RF Parameter'!I:I,'RF Parameter'!AB:AB) | E16: =_xlfn.XLOOKUP(A16,'RF Parameter'!I:I,'RF Parameter'!AA:AA) | F16: =_xlfn.XLOOKUP(A16,'RF Parameter'!I:I,'RF Parameter'!M:M) | G16: =_xlfn.XLOOKUP(A16,'RF Parameter'!I:I,'RF Parameter'!B:B) | H16: =G16 | K16: 4691 | L16: 46913 | M16: No | N16: 716 | O16: 17 | P16: 53 | Q16: 35652 | R16: 108 | S16: 106 | T16: 46913 | U16: 20 | V16: 43 | W16: 33 | X16: =Z16/5+1850.1 | Y16: =AA16/5+1850.1 | Z16: 487 | AA16: 87 | AB16: 5M

Sheet 4G
A1: Cell Name | B1: Site Name | C1: FMM | D1: Sector ID | E1: RRU Type | F1: TX/RX mode | G1: NE Name | H1: Band | I1: CrsPortNum | J1: eNodeB Name | K1: MORAN | L1: MCC | M1: MNC | N1: eNodeB ID | O1: CI | P1: Bandwidth(Mhz) | Q1: PCI | R1: TAC | S1: TAL | T1: DL Center Frequency | U1: UL Center Frequency | V1: DL UARFCN | W1: UL UARFCN | X1: RS Power(dBm) | Y1: TX Power/Port(W) | Z1: Pa | AA1: Pb | AB1: Cell Totally Power(W) | AC1: Uplink-Downlink Subframe Configuration | AD1: Special Subframe Configuration | AE1: PreambleFmt | AF1: Ncs | AG1: PrachConfIndex | AH1: RSI
A2: 01708171_IC_Pisco | B2: =_xlfn.XLOOKUP(A2,'RF Parameter'!I:I,'RF Parameter'!A:A) | C2: =_xlfn.XLOOKUP(A2,'RF Parameter'!I:I,'RF Parameter'!E:E) | D2: =_xlfn.XLOOKUP(A2,'RF Parameter'!I:I,'RF Parameter'!K:K) | E2: =_xlfn.XLOOKUP(A2,'RF Parameter'!I:I,'RF Parameter'!AB:AB) | F2: =_xlfn.XLOOKUP(A2,'RF Parameter'!I:I,'RF Parameter'!AA:AA) | G2: =_xlfn.XLOOKUP(A2,'RF Parameter'!I:I,'RF Parameter'!B:B) | H2: =_xlfn.XLOOKUP(A2,'RF Parameter'!I:I,'RF Parameter'!M:M) | I2: 4 | J2: =G2 | K2: - | L2: 716 | M2: 17 | N2: 817 | O2: 71 | P2: 15M | Q2: 27 | R2: 903 | S2: 45652 | T2: 765.5 | U2: 710.5 | V2: 9285 | W2: 27285 | X2: 14.2 | Y2: =ROUNDUP((10^((X2+Z2)/10)/1000)*LEFT(P2,2)*5*12,0) | Z2: 0 | AA2: 0 | AB2: =Y2*I2 | AC2: - | AD2: - | AE2: 0 | AF2: 10 | AG2: 3 | AH2: 184
A3: 01708172_IC_Pisco | B3: =_xlfn.XLOOKUP(A3,'RF Parameter'!I:I,'RF Parameter'!A:A) | C3: =_xlfn.XLOOKUP(A3,'RF Parameter'!I:I,'RF Parameter'!E:E) | D3: =_xlfn.XLOOKUP(A3,'RF Parameter'!I:I,'RF Parameter'!K:K) | E3: =_xlfn.XLOOKUP(A3,'RF Parameter'!I:I,'RF Parameter'!AB:AB) | F3: =_xlfn.XLOOKUP(A3,'RF Parameter'!I:I,'RF Parameter'!AA:AA) | G3: =_xlfn.XLOOKUP(A3,'RF Parameter'!I:I,'RF Parameter'!B:B) | H3: =_xlfn.XLOOKUP(A3,'RF Parameter'!I:I,'RF Parameter'!M:M) | I3: 4 | J3: =G3 | K3: - | L3: 716 | M3: 17 | N3: 817 | O3: 72 | P3: 15M | Q3: 28 | R3: 903 | S3: 45652 | T3: 765.5 | U3: 710.5 | V3: 9285 | W3: 27285 | X3: 12.2 | Y3: =ROUNDUP((10^((X3+Z3)/10)/1000)*LEFT(P3,2)*5*12,0) | Z3: 3 | AA3: 0 | AB3: =Y3*I3 | AC3: - | AD3: - | AE3: 0 | AF3: 10 | AG3: 3 | AH3: 208
A4: 01708173_IC_Pisco | B4: =_xlfn.XLOOKUP(A4,'RF Parameter'!I:I,'RF Parameter'!A:A) | C4: =_xlfn.XLOOKUP(A4,'RF Parameter'!I:I,'RF Parameter'!E:E) | D4: =_xlfn.XLOOKUP(A4,'RF Parameter'!I:I,'RF Parameter'!K:K) | E4: =_xlfn.XLOOKUP(A4,'RF Parameter'!I:I,'RF Parameter'!AB:AB) | F4: =_xlfn.XLOOKUP(A4,'RF Parameter'!I:I,'RF Parameter'!AA:AA) | G4: =_xlfn.XLOOKUP(A4,'RF Parameter'!I:I,'RF Parameter'!B:B) | H4: =_xlfn.XLOOKUP(A4,'RF Parameter'!I:I,'RF Parameter'!M:M) | I4: 4 | J4: =G4 | K4: - | L4: 716 | M4: 17 | N4: 817 | O4: 73 | P4: 15M | Q4: 29 | R4: 903 | S4: 45652 | T4: 765.5 | U4: 710.5 | V4: 9285 | W4: 27285 | X4: 12.2 | Y4: =ROUNDUP((10^((X4+Z4)/10)/1000)*LEFT(P4,2)*5*12,0) | Z4: 3 | AA4: 0 | AB4: =Y4*I4 | AC4: - | AD4: - | AE4: 0 | AF4: 10 | AG4: 3 | AH4: 216
A5: 01408171_IC_Pisco | B5: =_xlfn.XLOOKUP(A5,'RF Parameter'!I:I,'RF Parameter'!A:A) | C5: =_xlfn.XLOOKUP(A5,'RF Parameter'!I:I,'RF Parameter'!E:E) | D5: =_xlfn.XLOOKUP(A5,'RF Parameter'!I:I,'RF Parameter'!K:K) | E5: =_xlfn.XLOOKUP(A5,'RF Parameter'!I:I,'RF Parameter'!AB:AB) | F5: =_xlfn.XLOOKUP(A5,'RF Parameter'!I:I,'RF Parameter'!AA:AA) | G5: =_xlfn.XLOOKUP(A5,'RF Parameter'!I:I,'RF Parameter'!B:B) | H5: =_xlfn.XLOOKUP(A5,'RF Parameter'!I:I,'RF Parameter'!M:M) | I5: 4 | J5: =G5 | K5: - | L5: 716 | M5: 17 | N5: 817 | O5: 1 | P5: 20M | Q5: 384 | R5: 903 | S5: 45652 | T5: 2140 | U5: 1740 | V5: 2250 | W5: 20250 | X5: 18 | Y5: =ROUNDUP((10^((X5+Z5)/10)/1000)*LEFT(P5,2)*5*12,0) | Z5: -3 | AA5: 1 | AB5: =Y5*I5 | AC5: - | AD5: - | AE5: 0 | AF5: 10 | AG5: 3 | AH5: 520
A6: 01408172_IC_Pisco | B6: =_xlfn.XLOOKUP(A6,'RF Parameter'!I:I,'RF Parameter'!A:A) | C6: =_xlfn.XLOOKUP(A6,'RF Parameter'!I:I,'RF Parameter'!E:E) | D6: =_xlfn.XLOOKUP(A6,'RF Parameter'!I:I,'RF Parameter'!K:K) | E6: =_xlfn.XLOOKUP(A6,'RF Parameter'!I:I,'RF Parameter'!AB:AB) | F6: =_xlfn.XLOOKUP(A6,'RF Parameter'!I:I,'RF Parameter'!AA:AA) | G6: =_xlfn.XLOOKUP(A6,'RF Parameter'!I:I,'RF Parameter'!B:B) | H6: =_xlfn.XLOOKUP(A6,'RF Parameter'!I:I,'RF Parameter'!M:M) | I6: 4 | J6: =G6 | K6: - | L6: 716 | M6: 17 | N6: 817 | O6: 2 | P6: 20M | Q6: 385 | R6: 903 | S6: 45652 | T6: 2140 | U6: 1740 | V6: 2250 | W6: 20250 | X6: 15.2 | Y6: =ROUNDUP((10^((X6+Z6)/10)/1000)*LEFT(P6,2)*5*12,0) | Z6: -3 | AA6: 1 | AB6: =Y6*I6 | AC6: - | AD6: - | AE6: 0 | AF6: 10 | AG6: 3 | AH6: 16
A7: 01408177_IC_Pisco | B7: =_xlfn.XLOOKUP(A7,'RF Parameter'!I:I,'RF Parameter'!A:A) | C7: =_xlfn.XLOOKUP(A7,'RF Parameter'!I:I,'RF Parameter'!E:E) | D7: =_xlfn.XLOOKUP(A7,'RF Parameter'!I:I,'RF Parameter'!K:K) | E7: =_xlfn.XLOOKUP(A7,'RF Parameter'!I:I,'RF Parameter'!AB:AB) | F7: =_xlfn.XLOOKUP(A7,'RF Parameter'!I:I,'RF Parameter'!AA:AA) | G7: =_xlfn.XLOOKUP(A7,'RF Parameter'!I:I,'RF Parameter'!B:B) | H7: =_xlfn.XLOOKUP(A7,'RF Parameter'!I:I,'RF Parameter'!M:M) | I7: 4 | J7: =G7 | K7: - | L7: 716 | M7: 17 | N7: 817 | O7: 7 | P7: 20M | Q7: 60 | R7: 903 | S7: 45652 | T7: 2140 | U7: 1740 | V7: 2250 | W7: 20250 | X7: 15.2 | Y7: =ROUNDUP((10^((X7+Z7)/10)/1000)*LEFT(P7,2)*5*12,0) | Z7: -3 | AA7: 1 | AB7: =Y7*I7 | AC7: - | AD7: - | AE7: 0 | AF7: 10 | AG7: 3 | AH7: 152
A8: 01408173_IC_Pisco | B8: =_xlfn.XLOOKUP(A8,'RF Parameter'!I:I,'RF Parameter'!A:A) | C8: =_xlfn.XLOOKUP(A8,'RF Parameter'!I:I,'RF Parameter'!E:E) | D8: =_xlfn.XLOOKUP(A8,'RF Parameter'!I:I,'RF Parameter'!K:K) | E8: =_xlfn.XLOOKUP(A8,'RF Parameter'!I:I,'RF Parameter'!AB:AB) | F8: =_xlfn.XLOOKUP(A8,'RF Parameter'!I:I,'RF Parameter'!AA:AA) | G8: =_xlfn.XLOOKUP(A8,'RF Parameter'!I:I,'RF Parameter'!B:B) | H8: =_xlfn.XLOOKUP(A8,'RF Parameter'!I:I,'RF Parameter'!M:M) | I8: 4 | J8: =G8 | K8: - | L8: 716 | M8: 17 | N8: 817 | O8: 3 | P8: 20M | Q8: 386 | R8: 903 | S8: 45652 | T8: 2140 | U8: 1740 | V8: 2250 | W8: 20250 | X8: 17 | Y8: =ROUNDUP((10^((X8+Z8)/10)/1000)*LEFT(P8,2)*5*12,0) | Z8: -3 | AA8: 1 | AB8: =Y8*I8 | AC8: - | AD8: - | AE8: 0 | AF8: 10 | AG8: 3 | AH8: 456
A9: 09408171_IC_Pisco | B9: =_xlfn.XLOOKUP(A9,'RF Parameter'!I:I,'RF Parameter'!A:A) | C9: =_xlfn.XLOOKUP(A9,'RF Parameter'!I:I,'RF Parameter'!E:E) | D9: =_xlfn.XLOOKUP(A9,'RF Parameter'!I:I,'RF Parameter'!K:K) | E9: =_xlfn.XLOOKUP(A9,'RF Parameter'!I:I,'RF Parameter'!AB:AB) | F9: =_xlfn.XLOOKUP(A9,'RF Parameter'!I:I,'RF Parameter'!AA:AA) | G9: =_xlfn.XLOOKUP(A9,'RF Parameter'!I:I,'RF Parameter'!B:B) | H9: =_xlfn.XLOOKUP(A9,'RF Parameter'!I:I,'RF Parameter'!M:M) | I9: 4 | J9: =G9 | K9: - | L9: 716 | M9: 17 | N9: 817 | O9: 191 | P9: 10M | Q9: 384 | R9: 903 | S9: 45652 | T9: 1968.8 | U9: 1888.8 | V9: 988 | W9: 18988 | X9: 16 | Y9: =ROUNDUP((10^((X9+Z9)/10)/1000)*LEFT(P9,2)*5*12,0) | Z9: -3 | AA9: 1 | AB9: =Y9*I9 | AC9: - | AD9: - | AE9: 0 | AF9: 10 | AG9: 3 | AH9: 520
A10: 09408172_IC_Pisco | B10: =_xlfn.XLOOKUP(A10,'RF Parameter'!I:I,'RF Parameter'!A:A) | C10: =_xlfn.XLOOKUP(A10,'RF Parameter'!I:I,'RF Parameter'!E:E) | D10: =_xlfn.XLOOKUP(A10,'RF Parameter'!I:I,'RF Parameter'!K:K) | E10: =_xlfn.XLOOKUP(A10,'RF Parameter'!I:I,'RF Parameter'!AB:AB) | F10: =_xlfn.XLOOKUP(A10,'RF Parameter'!I:I,'RF Parameter'!AA:AA) | G10: =_xlfn.XLOOKUP(A10,'RF Parameter'!I:I,'RF Parameter'!B:B) | H10: =_xlfn.XLOOKUP(A10,'RF Parameter'!I:I,'RF Parameter'!M:M) | I10: 4 | J10: =G10 | K10: - | L10: 716 | M10: 17 | N10: 817 | O10: 192 | P10: 10M | Q10: 385 | R10: 903 | S10: 45652 | T10: 1968.8 | U10: 1888.8 | V10: 988 | W10: 18988 | X10: 10.2 | Y10: =ROUNDUP((10^((X10+Z10)/10)/1000)*LEFT(P10,2)*5*12,0) | Z10: 0 | AA10: 1 | AB10: =Y10*I10 | AC10: - | AD10: - | AE10: 0 | AF10: 10 | AG10: 3 | AH10: 16
A11: 09408177_IC_Pisco | B11: =_xlfn.XLOOKUP(A11,'RF Parameter'!I:I,'RF Parameter'!A:A) | C11: =_xlfn.XLOOKUP(A11,'RF Parameter'!I:I,'RF Parameter'!E:E) | D11: =_xlfn.XLOOKUP(A11,'RF Parameter'!I:I,'RF Parameter'!K:K) | E11: =_xlfn.XLOOKUP(A11,'RF Parameter'!I:I,'RF Parameter'!AB:AB) | F11: =_xlfn.XLOOKUP(A11,'RF Parameter'!I:I,'RF Parameter'!AA:AA) | G11: =_xlfn.XLOOKUP(A11,'RF Parameter'!I:I,'RF Parameter'!B:B) | H11: =_xlfn.XLOOKUP(A11,'RF Parameter'!I:I,'RF Parameter'!M:M) | I11: 4 | J11: =G11 | K11: - | L11: 716 | M11: 17 | N11: 817 | O11: 197 | P11: 10M | Q11: 60 | R11: 903 | S11: 45652 | T11: 1968.8 | U11: 1888.8 | V11: 988 | W11: 18988 | X11: 10.2 | Y11: =ROUNDUP((10^((X11+Z11)/10)/1000)*LEFT(P11,2)*5*12,0) | Z11: -3 | AA11: 1 | AB11: =Y11*I11 | AC11: - | AD11: - | AE11: 0 | AF11: 10 | AG11: 3 | AH11: 152
A12: 09408173_IC_Pisco | B12: =_xlfn.XLOOKUP(A12,'RF Parameter'!I:I,'RF Parameter'!A:A) | C12: =_xlfn.XLOOKUP(A12,'RF Parameter'!I:I,'RF Parameter'!E:E) | D12: =_xlfn.XLOOKUP(A12,'RF Parameter'!I:I,'RF Parameter'!K:K) | E12: =_xlfn.XLOOKUP(A12,'RF Parameter'!I:I,'RF Parameter'!AB:AB) | F12: =_xlfn.XLOOKUP(A12,'RF Parameter'!I:I,'RF Parameter'!AA:AA) | G12: =_xlfn.XLOOKUP(A12,'RF Parameter'!I:I,'RF Parameter'!B:B) | H12: =_xlfn.XLOOKUP(A12,'RF Parameter'!I:I,'RF Parameter'!M:M) | I12: 4 | J12: =G12 | K12: - | L12: 716 | M12: 17 | N12: 817 | O12: 193 | P12: 10M | Q12: 386 | R12: 903 | S12: 45652 | T12: 1968.8 | U12: 1888.8 | V12: 988 | W12: 18988 | X12: 14.2 | Y12: =ROUNDUP((10^((X12+Z12)/10)/1000)*LEFT(P12,2)*5*12,0) | Z12: 0 | AA12: 1 | AB12: =Y12*I12 | AC12: - | AD12: - | AE12: 0 | AF12: 10 | AG12: 3 | AH12: 456
A13: 01608171_IC_B40_Pisco | B13: =_xlfn.XLOOKUP(A13,'RF Parameter'!I:I,'RF Parameter'!A:A) | C13: =_xlfn.XLOOKUP(A13,'RF Parameter'!I:I,'RF Parameter'!E:E) | D13: =_xlfn.XLOOKUP(A13,'RF Parameter'!I:I,'RF Parameter'!K:K) | E13: =_xlfn.XLOOKUP(A13,'RF Parameter'!I:I,'RF Parameter'!AB:AB) | F13: =_xlfn.XLOOKUP(A13,'RF Parameter'!I:I,'RF Parameter'!AA:AA) | G13: =_xlfn.XLOOKUP(A13,'RF Parameter'!I:I,'RF Parameter'!B:B) | H13: =_xlfn.XLOOKUP(A13,'RF Parameter'!I:I,'RF Parameter'!M:M) | I13: 2 | J13: =G13 | K13: - | L13: 716 | M13: 17 | N13: 817 | O13: 231 | P13: 15M | Q13: 384 | R13: 903 | S13: 45652 | T13: 2367.5 | U13: - | V13: 39325 | W13: - | X13: 15 | Y13: =ROUNDUP((10^((X13+Z13)/10)/1000)*LEFT(P13,2)*5*12,0) | Z13: -3 | AA13: 1 | AB13: =Y13*I13 | AC13: 2 | AD13: 7 | AE13: 0 | AF13: 10 | AG13: 0 | AH13: 520
A14: 01608176_IC_B40_Pisco | B14: =_xlfn.XLOOKUP(A14,'RF Parameter'!I:I,'RF Parameter'!A:A) | C14: =_xlfn.XLOOKUP(A14,'RF Parameter'!I:I,'RF Parameter'!E:E) | D14: =_xlfn.XLOOKUP(A14,'RF Parameter'!I:I,'RF Parameter'!K:K) | E14: =_xlfn.XLOOKUP(A14,'RF Parameter'!I:I,'RF Parameter'!AB:AB) | F14: =_xlfn.XLOOKUP(A14,'RF Parameter'!I:I,'RF Parameter'!AA:AA) | G14: =_xlfn.XLOOKUP(A14,'RF Parameter'!I:I,'RF Parameter'!B:B) | H14: =_xlfn.XLOOKUP(A14,'RF Parameter'!I:I,'RF Parameter'!M:M) | I14: 2 | J14: =G14 | K14: - | L14: 716 | M14: 17 | N14: 817 | O14: 236 | P14: 15M | Q14: 27 | R14: 903 | S14: 45652 | T14: 2382.5 | U14: - | V14: 39475 | W14: - | X14: 15 | Y14: =ROUNDUP((10^((X14+Z14)/10)/1000)*LEFT(P14,2)*5*12,0) | Z14: -3 | AA14: 1 | AB14: =Y14*I14 | AC14: 2 | AD14: 7 | AE14: 0 | AF14: 10 | AG14: 0 | AH14: 184
A15: 01608172_IC_B40_Pisco | B15: =_xlfn.XLOOKUP(A15,'RF Parameter'!I:I,'RF Parameter'!A:A) | C15: =_xlfn.XLOOKUP(A15,'RF Parameter'!I:I,'RF Parameter'!E:E) | D15: =_xlfn.XLOOKUP(A15,'RF Parameter'!I:I,'RF Parameter'!K:K) | E15: =_xlfn.XLOOKUP(A15,'RF Parameter'!I:I,'RF Parameter'!AB:AB) | F15: =_xlfn.XLOOKUP(A15,'RF Parameter'!I:I,'RF Parameter'!AA:AA) | G15: =_xlfn.XLOOKUP(A15,'RF Parameter'!I:I,'RF Parameter'!B:B) | H15: =_xlfn.XLOOKUP(A15,'RF Parameter'!I:I,'RF Parameter'!M:M) | I15: 2 | J15: =G15 | K15: - | L15: 716 | M15: 17 | N15: 817 | O15: 232 | P15: 15M | Q15: 385 | R15: 903 | S15: 45652 | T15: 2367.5 | U15: - | V15: 39325 | W15: - | X15: 12.2 | Y15: =ROUNDUP((10^((X15+Z15)/10)/1000)*LEFT(P15,2)*5*12,0) | Z15: -3 | AA15: 1 | AB15: =Y15*I15 | AC15: 2 | AD15: 7 | AE15: 0 | AF15: 10 | AG15: 0 | AH15: 16
A16: 01608177_IC_B40_Pisco | B16: =_xlfn.XLOOKUP(A16,'RF Parameter'!I:I,'RF Parameter'!A:A) | C16: =_xlfn.XLOOKUP(A16,'RF Parameter'!I:I,'RF Parameter'!E:E) | D16: =_xlfn.XLOOKUP(A16,'RF Parameter'!I:I,'RF Parameter'!K:K) | E16: =_xlfn.XLOOKUP(A16,'RF Parameter'!I:I,'RF Parameter'!AB:AB) | F16: =_xlfn.XLOOKUP(A16,'RF Parameter'!I:I,'RF Parameter'!AA:AA) | G16: =_xlfn.XLOOKUP(A16,'RF Parameter'!I:I,'RF Parameter'!B:B) | H16: =_xlfn.XLOOKUP(A16,'RF Parameter'!I:I,'RF Parameter'!M:M) | I16: 2 | J16: =G16 | K16: - | L16: 716 | M16: 17 | N16: 817 | O16: 237 | P16: 15M | Q16: 28 | R16: 903 | S16: 45652 | T16: 2382.5 | U16: - | V16: 39475 | W16: - | X16: 12.2 | Y16: =ROUNDUP((10^((X16+Z16)/10)/1000)*LEFT(P16,2)*5*12,0) | Z16: -3 | AA16: 1 | AB16: =Y16*I16 | AC16: 2 | AD16: 7 | AE16: 0 | AF16: 10 | AG16: 0 | AH16: 208
A17: 01608173_IC_B40_Pisco | B17: =_xlfn.XLOOKUP(A17,'RF Parameter'!I:I,'RF Parameter'!A:A) | C17: =_xlfn.XLOOKUP(A17,'RF Parameter'!I:I,'RF Parameter'!E:E) | D17: =_xlfn.XLOOKUP(A17,'RF Parameter'!I:I,'RF Parameter'!K:K) | E17: =_xlfn.XLOOKUP(A17,'RF Parameter'!I:I,'RF Parameter'!AB:AB) | F17: =_xlfn.XLOOKUP(A17,'RF Parameter'!I:I,'RF Parameter'!AA:AA) | G17: =_xlfn.XLOOKUP(A17,'RF Parameter'!I:I,'RF Parameter'!B:B) | H17: =_xlfn.XLOOKUP(A17,'RF Parameter'!I:I,'RF Parameter'!M:M) | I17: 2 | J17: =G17 | K17: - | L17: 716 | M17: 17 | N17: 817 | O17: 233 | P17: 15M | Q17: 386 | R17: 903 | S17: 45652 | T17: 2367.5 | U17: - | V17: 39325 | W17: - | X17: 14 | Y17: =ROUNDUP((10^((X17+Z17)/10)/1000)*LEFT(P17,2)*5*12,0) | Z17: -3 | AA17: 1 | AB17: =Y17*I17 | AC17: 2 | AD17: 7 | AE17: 0 | AF17: 10 | AG17: 0 | AH17: 456
A18: 01608178_IC_B40_Pisco | B18: =_xlfn.XLOOKUP(A18,'RF Parameter'!I:I,'RF Parameter'!A:A) | C18: =_xlfn.XLOOKUP(A18,'RF Parameter'!I:I,'RF Parameter'!E:E) | D18: =_xlfn.XLOOKUP(A18,'RF Parameter'!I:I,'RF Parameter'!K:K) | E18: =_xlfn.XLOOKUP(A18,'RF Parameter'!I:I,'RF Parameter'!AB:AB) | F18: =_xlfn.XLOOKUP(A18,'RF Parameter'!I:I,'RF Parameter'!AA:AA) | G18: =_xlfn.XLOOKUP(A18,'RF Parameter'!I:I,'RF Parameter'!B:B) | H18: =_xlfn.XLOOKUP(A18,'RF Parameter'!I:I,'RF Parameter'!M:M) | I18: 2 | J18: =G18 | K18: - | L18: 716 | M18: 17 | N18: 817 | O18: 238 | P18: 15M | Q18: 29 | R18: 903 | S18: 45652 | T18: 2382.5 | U18: - | V18: 39475 | W18: - | X18: 14 | Y18: =ROUNDUP((10^((X18+Z18)/10)/1000)*LEFT(P18,2)*5*12,0) | Z18: -3 | AA18: 1 | AB18: =Y18*I18 | AC18: 2 | AD18: 7 | AE18: 0 | AF18: 10 | AG18: 0 | AH18: 216
A19: 01722471_IC_San_Clemente | B19: =_xlfn.XLOOKUP(A19,'RF Parameter'!I:I,'RF Parameter'!A:A) | C19: =_xlfn.XLOOKUP(A19,'RF Parameter'!I:I,'RF Parameter'!E:E) | D19: =_xlfn.XLOOKUP(A19,'RF Parameter'!I:I,'RF Parameter'!K:K) | E19: =_xlfn.XLOOKUP(A19,'RF Parameter'!I:I,'RF Parameter'!AB:AB) | F19: =_xlfn.XLOOKUP(A19,'RF Parameter'!I:I,'RF Parameter'!AA:AA) | G19: =_xlfn.XLOOKUP(A19,'RF Parameter'!I:I,'RF Parameter'!B:B) | H19: =_xlfn.XLOOKUP(A19,'RF Parameter'!I:I,'RF Parameter'!M:M) | I19: 4 | J19: =G19 | K19: - | L19: 716 | M19: 17 | N19: 2247 | O19: 71 | P19: 15M | Q19: 262 | R19: 903 | S19: 45652 | T19: 765.5 | U19: 710.5 | V19: 9285 | W19: 27285 | X19: 12.2 | Y19: =ROUNDUP((10^((X19+Z19)/10)/1000)*LEFT(P19,2)*5*12,0) | Z19: 0 | AA19: 0 | AB19: =Y19*I19 | AC19: - | AD19: - | AE19: 0 | AF19: 10 | AG19: 3 | AH19: 304
A20: 01722472_IC_San_Clemente | B20: =_xlfn.XLOOKUP(A20,'RF Parameter'!I:I,'RF Parameter'!A:A) | C20: =_xlfn.XLOOKUP(A20,'RF Parameter'!I:I,'RF Parameter'!E:E) | D20: =_xlfn.XLOOKUP(A20,'RF Parameter'!I:I,'RF Parameter'!K:K) | E20: =_xlfn.XLOOKUP(A20,'RF Parameter'!I:I,'RF Parameter'!AB:AB) | F20: =_xlfn.XLOOKUP(A20,'RF Parameter'!I:I,'RF Parameter'!AA:AA) | G20: =_xlfn.XLOOKUP(A20,'RF Parameter'!I:I,'RF Parameter'!B:B) | H20: =_xlfn.XLOOKUP(A20,'RF Parameter'!I:I,'RF Parameter'!M:M) | I20: 4 | J20: =G20 | K20: - | L20: 716 | M20: 17 | N20: 2247 | O20: 72 | P20: 15M | Q20: 261 | R20: 903 | S20: 45652 | T20: 765.5 | U20: 710.5 | V20: 9285 | W20: 27285 | X20: 11.2 | Y20: =ROUNDUP((10^((X20+Z20)/10)/1000)*LEFT(P20,2)*5*12,0) | Z20: 0 | AA20: 0 | AB20: =Y20*I20 | AC20: - | AD20: - | AE20: 0 | AF20: 10 | AG20: 3 | AH20: 88
